Workbook

Sheet Recon
A1: Member | B1: Balance Brought Forward | C1: July 2021 - April 2022 Cont (Planned) | D1: Total July 2021 - April 2022 Cont (Planned)2 | E1: Contribution made (Actual) | F1: Outstanding | G1: % outstanding | H1: Column1 | J1: Members in good standing (not owing) | K1: Members owing < 10% | L1: Members owing < 20% | M1: Members owing < 30% | N1: Members owing < 50% | O1: Members owing < 65% | P1: Members owing > 65%
A2: Member 1 | B2: 500 | C2: =200*10 -> 2000 | D2: =B2+C2 -> 2500 | E2: 2200 | F2: =B2+C2-E2 -> 300 | G2: =F2/D2 -> 0.12 | J2: 9 | K2: 2 | L2: 4 | M2: 1 | N2: 2 | O2: 2 | P2: 67
A3: Member 2 | B3: 1100 | C3: =200*10 -> 2000 | D3: =B3+C3 -> 3100 | E3: 1400 | F3: =B3+C3-E3 -> 1700 | G3: =F3/D3 -> 0.5483871 | P3: =SUM(J2:P2) -> 87
A4: Member 3 | B4: 5700 | C4: =200*10 -> 2000 | D4: =B4+C4 -> 7700 | E4: 0 | F4: =B4+C4-E4 -> 7700 | G4: =F4/D4 -> 1
A5: Member 4 | B5: 7000 | C5: =200*10 -> 2000 | D5: =B5+C5 -> 9000 | E5: 0 | F5: =B5+C5-E5 -> 9000 | G5: =F5/D5 -> 1
A6: Member 5 | B6: 1761.33 | C6: =200*10 -> 2000 | D6: =B6+C6 -> 3761.33 | E6: 0 | F6: =B6+C6-E6 -> 3761.33 | G6: =F6/D6 -> 1
A7: Member 6 | B7: 4100 | C7: =200*10 -> 2000 | D7: =B7+C7 -> 6100 | E7: 500 | F7: =B7+C7-E7 -> 5600 | G7: =F7/D7 -> 0.91803279
A8: Member 7 | B8: 7300 | C8: 2000 | D8: =B8+C8 -> 9300 | E8: 0 | F8: =B8+C8-E8 -> 9300 | G8: =F8/D8 -> 1
A9: Member 8 | B9: 5100 | C9: =200*10 -> 2000 | D9: =B9+C9 -> 7100 | E9: 200 | F9: =B9+C9-E9 -> 6900 | G9: =F9/D9 -> 0.97183099
A10: Member 9 | B10: 2400 | C10: =200*10 -> 2000 | D10: =B10+C10 -> 4400 | E10: 0 | F10: =B10+C10-E10 -> 4400 | G10: =F10/D10 -> 1
A11: Member 10 | B11: 6600 | C11: =200*10 -> 2000 | D11: =B11+C11 -> 8600 | E11: 800 | F11: =B11+C11-E11 -> 7800 | G11: =F11/D11 -> 0.90697674
A12: Member 11 | B12: 850 | C12: =200*10 -> 2000 | D12: =B12+C12 -> 2850 | E12: 0 | F12: =B12+C12-E12 -> 2850 | G12: =F12/D12 -> 1
A13: Member 12 | B13: -650 | C13: =200*10 -> 2000 | D13: =B13+C13 -> 1350 | E13: 1300 | F13: =B13+C13-E13 -> 50 | G13: =F13/D13 -> 0.037037037
A14: Member 13 | B14: 500 | C14: =200*10 -> 2000 | D14: =B14+C14 -> 2500 | E14: 0 | F14: =B14+C14-E14 -> 2500 | G14: =F14/D14 -> 1
A15: Member 14 | B15: 7100 | C15: =200*10 -> 2000 | D15: =B15+C15 -> 9100 | E15: 800 | F15: =B15+C15-E15 -> 8300 | G15: =F15/D15 -> 0.91208791
A16: Member 15 | B16: 5100 | C16: =200*10 -> 2000 | D16: =B16+C16 -> 7100 | E16: 0 | F16: =B16+C16-E16 -> 7100 | G16: =F16/D16 -> 1
A17: Member 16 | B17: 5900 | C17: =200*10 -> 2000 | D17: =B17+C17 -> 7900 | E17: 0 | F17: =B17+C17-E17 -> 7900 | G17: =F17/D17 -> 1
A18: Member 17 | B18: -4100 | C18: =200*10 -> 2000 | D18: =B18+C18 -> -2100 | E18: 1500 | F18: 0 | G18: =F18/D18 -> 0 | H18: =2100+1500 -> 3600
A19: Member 18 | B19: 100 | C19: =200*10 -> 2000 | D19: =B19+C19 -> 2100 | E19: 1400 | F19: =B19+C19-E19 -> 700 | G19: =F19/D19 -> 0.33333333
A20: Member 19 | B20: 6700 | C20: =200*10 -> 2000 | D20: =B20+C20 -> 8700 | E20: 0 | F20: =B20+C20-E20 -> 8700 | G20: =F20/D20 -> 1 | J20: Members in good standing (not owing) | K20: Members owing < 10% | L20: Members owing < 20% | M20: Members owing < 30% | N20: Members owing < 50% | O20: Members owing < 65% | P20: Members owing > 65%
A21: Member 20 | B21: 430 | C21: =200*10 -> 2000 | D21: =B21+C21 -> 2430 | E21: 200 | F21: =B21+C21-E21 -> 2230 | G21: =F21/D21 -> 0.91769547 | I21: 86 | J21: =J2/I21 -> 0.10465116 | K21: =K2/I21 -> 0.023255814 | L21: =L2/I21 -> 0.046511628 | M21: =M2/I21 -> 0.011627907 | N21: =N2/I21 -> 0.023255814 | O21: =O2/I21 -> 0.023255814 | P21: =P2/I21 -> 0.77906977
A22: Member 21 | B22: 5900 | C22: =200*10 -> 2000 | D22: =B22+C22 -> 7900 | E22: 0 | F22: =B22+C22-E22 -> 7900 | G22: =F22/D22 -> 1
A23: Member 22 | B23: 2700 | C23: =200*10 -> 2000 | D23: =B23+C23 -> 4700 | E23: 200 | F23: =B23+C23-E23 -> 4500 | G23: =F23/D23 -> 0.95744681
A24: Member 23 | B24: 6700 | C24: =200*10 -> 2000 | D24: =B24+C24 -> 8700 | E24: 0 | F24: =B24+C24-E24 -> 8700 | G24: =F24/D24 -> 1
A25: Member 24 | B25: 0 | C25: =200*10 -> 2000 | D25: =B25+C25 -> 2000 | E25: 2700 | F25: 0 | G25: =F25/D25 -> 0 | H25: =Table1[[#This Row],[Contribution made (Actual)]]-Table1[[#This Row],[Total July 2021 - April 2022 Cont (Planned)2]] -> 700
A26: Member 25 | B26: 350 | C26: =200*10 -> 2000 | D26: =B26+C26 -> 2350 | E26: 2700 | F26: 0 | G26: =F26/D26 -> 0 | H26: =Table1[[#This Row],[Contribution made (Actual)]]-Table1[[#This Row],[Total July 2021 - April 2022 Cont (Planned)2]] -> 350
A27: Member 26 | B27: 5100 | C27: =200*10 -> 2000 | D27: =B27+C27 -> 7100 | E27: 0 | F27: =B27+C27-E27 -> 7100 | G27: =F27/D27 -> 1
A28: Member 27 | B28: 6100 | C28: =200*10 -> 2000 | D28: =B28+C28 -> 8100 | E28: 0 | F28: =B28+C28-E28 -> 8100 | G28: =F28/D28 -> 1
A29: Member 28 | B29: 6700 | C29: =200*10 -> 2000 | D29: =B29+C29 -> 8700 | E29: 0 | F29: =B29+C29-E29 -> 8700 | G29: =F29/D29 -> 1
A30: Member 29 | B30: 1600 | C30: =200*10 -> 2000 | D30: =B30+C30 -> 3600 | E30: 0 | F30: =B30+C30-E30 -> 3600 | G30: =F30/D30 -> 1
A31: Member 30 | B31: 1100 | C31: =200*10 -> 2000 | D31: =B31+C31 -> 3100 | E31: 3300 | F31: 0 | G31: =F31/D31 -> 0 | H31: =Table1[[#This Row],[Contribution made (Actual)]]-Table1[[#This Row],[Total July 2021 - April 2022 Cont (Planned)2]] -> 200
A32: Member 31 | B32: 400 | C32: =200*10 -> 2000 | D32: =B32+C32 -> 2400 | E32: 2500 | F32: 0 | G32: =F32/D32 -> 0 | H32: =Table1[[#This Row],[Contribution made (Actual)]]-Table1[[#This Row],[Total July 2021 - April 2022 Cont (Planned)2]] -> 100
A33: Member 32 | B33: 5900 | C33: =200*10 -> 2000 | D33: =B33+C33 -> 7900 | E33: 0 | F33: =B33+C33-E33 -> 7900 | G33: =F33/D33 -> 1
A34: Member 33 | B34: 7300 | C34: 2000 | D34: =B34+C34 -> 9300 | E34: 500 | F34: =B34+C34-E34 -> 8800 | G34: =F34/D34 -> 0.94623656
A35: Member 34 | B35: 6700 | C35: =200*10 -> 2000 | D35: =B35+C35 -> 8700 | E35: 0 | F35: =B35+C35-E35 -> 8700 | G35: =F35/D35 -> 1
A36: Member 35 | B36: 7300 | C36: =200*10 -> 2000 | D36: =B36+C36 -> 9300 | E36: 1100 | F36: =B36+C36-E36 -> 8200 | G36: =F36/D36 -> 0.88172043
A37: Member 36 | B37: 3900 | C37: 2000 | D37: =B37+C37 -> 5900 | E37: 0 | F37: =B37+C37-E37 -> 5900 | G37: =F37/D37 -> 1
A38: Member 37 | B38: 3850 | C38: =200*10 -> 2000 | D38: =B38+C38 -> 5850 | E38: 400 | F38: =B38+C38-E38 -> 5450 | G38: =F38/D38 -> 0.93162393
A39: Member 38 | B39: 6700 | C39: =200*10 -> 2000 | D39: =B39+C39 -> 8700 | E39: 0 | F39: =B39+C39-E39 -> 8700 | G39: =F39/D39 -> 1
A40: Member 39 | B40: 4890 | C40: =200*10 -> 2000 | D40: =B40+C40 -> 6890 | E40: 690 | F40: =B40+C40-E40 -> 6200 | G40: =F40/D40 -> 0.89985486
...

Sheet 2018-2019 B STATEMENT 
A1: TransactionDate | B1: Amount | C1: Fee | D1: Group | E1: Member | F1: PayType | G1: Reference | H1: Bank Charge
A2: 43284.75 | B2: 150 | C2: 1.335 | D2: Peoples Liberator Fund | F2: EFT | G2: 115719367211
A3: 43290.723 | B3: 100 | C3: 9.99 | D3: Peoples Liberator Fund | F3: EFT | G3: 115719367251
A4: 43290.723 | B4: 100 | C4: 0.89 | D4: Peoples Liberator Fund | F4: EFT | G4: 115719367255
A5: 43291.744 | B5: 300 | C5: 2.67 | D5: Peoples Liberator Fund | F5: EFT | G5: 115719367269
A6: 43291.748 | B6: 150 | C6: 1.335 | D6: Peoples Liberator Fund | F6: EFT | G6: 115719367213
A7: 43292.746 | B7: 200 | C7: 1.78 | D7: Peoples Liberator Fund | F7: EFT | G7: 115719367302
A8: 43292.746 | B8: 300 | C8: 2.67 | D8: Peoples Liberator Fund | F8: EFT | G8: 115719367243
A9: 43293.722 | B9: 300 | C9: 2.67 | D9: Peoples Liberator Fund | F9: EFT | G9: 115719367253
A10: 43294.744 | B10: 300 | C10: 2.67 | D10: Peoples Liberator Fund | F10: EFT | G10: 115719367265
A11: 43294.744 | B11: 200 | C11: 1.78 | D11: Peoples Liberator Fund | F11: EFT | G11: 115719367211
A12: 43306.743 | B12: 300 | C12: 2.67 | D12: Peoples Liberator Fund | F12: EFT | G12: 115719367362
A13: 43307.743 | B13: 100 | C13: 0.89 | D13: Peoples Liberator Fund | F13: EFT | G13: 115719367421
... A16: 43310.655 | B16: 300 | C16: 9.99 | D16: Peoples Liberator Fund | F16: Retail Shop | G16: 115719367441
A17: 43311.744 | B17: 300 | C17: 2.67 | D17: Peoples Liberator Fund | F17: EFT | G17: 115719367256 | H17: =C17/B17*100 -> 0.89
A18: 43311.744 | B18: 310 | C18: 9.99 | D18: Peoples Liberator Fund | F18: EFT | G18: 115719367414
A19: 43311.744 | B19: 200 | C19: 1.78 | D19: Peoples Liberator Fund | F19: EFT | G19: 115719367255
A20: 43312.715 | B20: 400 | C20: 3.56 | D20: Peoples Liberator Fund | F20: EFT | G20: 115719367421
A21: 43312.715 | B21: 300 | C21: 2.67 | D21: Peoples Liberator Fund | F21: EFT | G21: 115719367410
A22: 43312.715 | B22: 300 | C22: 2.67 | D22: Peoples Liberator Fund | F22: EFT | G22: 115719367446
A23: 43312.715 | B23: 300 | C23: 2.67 | D23: Peoples Liberator Fund | F23: EFT | G23: 115719367252
A24: 43312.715 | B24: 300 | C24: 2.67 | D24: Peoples Liberator Fund | F24: EFT | G24: 115719367447
A25: 43312.715 | B25: 300 | C25: 2.67 | D25: Peoples Liberator Fund | F25: EFT | G25: 115719367360 | H25: =C25/B25*100 -> 0.89
A26: 43312.715 | B26: 300 | C26: 2.67 | D26: Peoples Liberator Fund | F26: EFT | G26: 115719367448
A27: 43312.715 | B27: 200 | C27: 1.78 | D27: Peoples Liberator Fund | F27: EFT | G27: 115719367213
A28: 43313.743 | B28: 300 | C28: 2.67 | D28: Peoples Liberator Fund | F28: EFT | G28: 115719367430
A29: 43314.688 | B29: 300 | C29: 2.67 | D29: Peoples Liberator Fund | F29: EFT | G29: 115719367450
A30: 43318.684 | B30: 200 | C30: 1.78 | D30: Peoples Liberator Fund | F30: EFT | G30: 115719367269
A31: 43318.684 | B31: 400 | C31: 9.99 | D31: Peoples Liberator Fund | F31: EFT | G31: 115719367464
A32: 43318.684 | B32: 300 | C32: 2.67 | D32: Peoples Liberator Fund | F32: EFT | G32: 115719367474
A33: 43318.684 | B33: 300 | C33: 2.67 | D33: Peoples Liberator Fund | F33: EFT | G33: 115719367428
A34: 43320.724 | B34: 300 | C34: 2.67 | D34: Peoples Liberator Fund | F34: EFT | G34: 115719367440
A35: 43320.724 | B35: 300 | C35: 2.67 | D35: Peoples Liberator Fund | F35: EFT | G35: 115719367364
A36: 43328.75 | B36: 200 | C36: 1.78 | D36: Peoples Liberator Fund | F36: EFT | G36: 115719367265
A37: 43328.75 | B37: 200 | C37: 1.78 | D37: Peoples Liberator Fund | F37: EFT | G37: 115719367447
A38: 43332.717 | B38: 300 | C38: 2.67 | D38: Peoples Liberator Fund | F38: EFT | G38: 115719367501
A39: 43332.717 | B39: 200 | C39: 1.78 | D39: Peoples Liberator Fund | F39: EFT | G39: 115719367256 | H39: =C39/B39*100 -> 0.89
A40: 43332.717 | B40: 500 | C40: 4.45 | D40: Peoples Liberator Fund | F40: EFT | G40: 115719367411
A41: 43332.717 | B41: 300 | C41: 2.67 | D41: Peoples Liberator Fund | F41: EFT | G41: 115719367466
A42: 43332.717 | B42: 300 | C42: 2.67 | D42: Peoples Liberator Fund | F42: EFT | G42: 115719367472
...

Sheet  2018-2019
A1: Member | B1: Date Join | C1: Membership Fee | D1: Expected Contribution | E1: Balance Brought Forward (Catch-up fee) | F1: Catch-Up Fee | G1: Estimated 12 Months Contribution (Jul 2018-June 2019) | H1: Total Contribution incl membership fee for 12 Months | I1: Total outstanding contribution for 12 Months | J1: Closing Balance (Inc. Penalties) | K1: Total Bank Charges @ 0,89% | L1: Total Interest Earned @ 5,5% | M1: Penalty | N1: Share Value | O1: 43282 | P1: Bank Charges @ 0,89% | Q1: Penalty | R1: 43313 | S1: Bank Charges @ 0,89% | T1: Penalty | U1: 43344 | V1: Bank Charges @ 0,89% | W1: Penalty | X1: 43374 | Y1: Bank Charges @ 0,89% | Z1: Penalty | AA1: 43405 | AB1: Bank Charges @ 0,89% | AC1: Penalty | AD1: 43435 | AE1: Bank Charges @ 0,89% | AF1: Penalty | AG1: 43466 | AH1: Bank Charges @ 0,89% | AI1: Penalty | AJ1: 43497 | AK1: Bank Charges @ 0,89% | AL1: Penalty | AM1: 43525 | AN1: Bank Charges @ 0,99% | AO1: Penalty | AP1: 43556 | AQ1: Bank Charges @ 0,99% | AR1: Penalty | AS1: 43586 | AT1: Bank Charges @ 0,99% | AU1: Penalty | AV1: 43617 | AW1: Bank Charges @ 0,99% | AX1: Penalty | AY1: Total Contribution for Current Year
A2: Member 1 | B2: 14/08/2018 | C2: 100 | D2: =200*12 -> 2400 | E2: 0 | F2: ='Catch up Fee'!D2 -> 200 | G2: =C2+D2 -> 2500 | H2: =AY2 -> 1700 | I2: =G2-H2 -> 800 | J2: =I2+M2 -> 800 | K2: =P2+S2+V2+Y2+AB2+AE2+AH2+AK2+AN2+AQ2+AT2+AW2 -> 15.73 | L2: =(H2-K2-C2)*5.5% -> 87.13485 | M2: 0 | N2: =H2-K2-M2+L2 -> 1771.4048 | O2: 0 | P2: =O2*0.89% -> 0 | Q2: 0 | S2: =R2*0.89% -> 0 | T2: 0 | U2: ='2018-2019 B STATEMENT '!B38+'2018-2019 B STATEMENT '!B62 -> 500 | V2: =U2*0.89% -> 4.45 | W2: 0 | X2: ='2018-2019 B STATEMENT '!B102 -> 200 | Y2: =X2*0.89% -> 1.78 | Z2: 0 | AA2: ='2018-2019 B STATEMENT '!B140 -> 400 | AB2: =AA2*0.89% -> 3.56 | AC2: 0 | AD2: 0 | AE2: =AD2*0.89% -> 0 | AF2: 0 | AG2: 0 | AH2: =AG2*0.89% -> 0 | AI2: 0 | AJ2: 0 | AK2: =AJ2*0.89% -> 0 | AL2: 0 | AM2: ='2018-2019 B STATEMENT '!B233 -> 600 | AN2: =AM2*0.99% -> 5.94 | AO2: 0 | AP2: 0 | AQ2: =AP2*0.99% -> 0 | AR2: 0 | AS2: 0 | AT2: =AS2*0.99% -> 0 | AU2: 0 | AV2: 0 | AW2: =AV2*0.99% -> 0 | AX2: 0 | AY2: =O2+R2+U2+X2+AA2+AD2+AJ2+AG2+AM2+AP2+AS2+AV2 -> 1700
A3: Member 2 | B3: 16/02/2019 | C3: 100 | D3: =200*12 -> 2400 | E3: 0 | F3: ='Catch up Fee'!D3 -> 1600 | G3: =C3+D3 -> 2500 | H3: =AY3 -> 2500 | I3: =G3-H3 -> 0 | J3: =I3+M3 -> 0 | K3: =P3+S3+V3+Y3+AB3+AE3+AH3+AK3+AN3+AQ3+AT3+AW3 -> 24.75 | L3: =(H3-K3-C3)*5.5% -> 130.63875 | M3: 0 | N3: =H3-K3-M3+L3 -> 2605.8888 | O3: 0 | P3: =O3*0.89% -> 0 | Q3: 0 | R3: 0 | S3: =R3*0.89% -> 0 | T3: 0 | U3: 0 | V3: =U3*0.89% -> 0 | W3: 0 | X3: 0 | Y3: =X3*0.89% -> 0 | Z3: 0 | AA3: 0 | AB3: =AA3*0.89% -> 0 | AC3: 0 | AD3: 0 | AE3: =AD3*0.89% -> 0 | AF3: 0 | AG3: 0 | AH3: =AG3*0.89% -> 0 | AI3: 0 | AJ3: 0 | AK3: =AJ3*0.89% -> 0 | AL3: 0 | AM3: 0 | AN3: =AM3*0.99% -> 0 | AO3: 0 | AP3: 2500 | AQ3: =AP3*0.99% -> 24.75 | AR3: 0 | AS3: 0 | AT3: =AS3*0.99% -> 0 | AU3: 0 | AV3: 0 | AW3: =AV3*0.99% -> 0 | AX3: 0 | AY3: =O3+R3+U3+X3+AA3+AD3+AJ3+AG3+AM3+AP3+AS3+AV3 -> 2500
A4: Member 3 | B4: 30/07/2018 | C4: 100 | D4: =200*12 -> 2400 | E4: 0 | F4: ='Catch up Fee'!D4 -> 0 | G4: =C4+D4 -> 2500 | H4: =AY4 -> 1500 | I4: =G4-H4-C4 -> 900 | J4: =I4+M4 -> 900 | K4: =P4+S4+V4+Y4+AB4+AE4+AH4+AK4+AN4+AQ4+AT4+AW4 -> 14.35 | L4: =(H4-K4-C4)*5.5% -> 76.21075 | M4: 0 | N4: =H4-K4-M4+L4 -> 1561.8608 | O4: 0 | P4: =O4*0.89% -> 0 | Q4: 0 | R4: 0 | S4: =R4*0.89% -> 0 | T4: 0 | U4: ='2018-2019 B STATEMENT '!B63 -> 500 | V4: =U4*0.89% -> 4.45 | W4: 0 | X4: 0 | Y4: =X4*0.89% -> 0 | Z4: 0 | AA4: 0 | AB4: =AA4*0.89% -> 0 | AC4: 0 | AD4: 0 | AE4: =AD4*0.89% -> 0 | AF4: 0 | AG4: 0 | AH4: =AG4*0.89% -> 0 | AI4: 0 | AJ4: 0 | AK4: =AJ4*0.89% -> 0 | AL4: 0 | AM4: ='2018-2019 B STATEMENT '!B209 -> 500 | AN4: =AM4*0.99% -> 4.95 | AO4: 0 | AP4: ='2018-2019 B STATEMENT '!B260 -> 500 | AQ4: =AP4*0.99% -> 4.95 | AR4: 0 | AS4: 0 | AT4: =AS4*0.99% -> 0 | AU4: 0 | AV4: 0 | AW4: =AV4*0.99% -> 0 | AX4: 0 | AY4: =O4+R4+U4+X4+AA4+AD4+AJ4+AG4+AM4+AP4+AS4+AV4 -> 1500
A5: Member 4 | B5: 11/7/2018 | C5: 100 | D5: =200*12 -> 2400 | E5: 0 | F5: ='Catch up Fee'!D5 -> 0 | G5: =C5+D5 -> 2500 | H5: =AY5 -> 200 | I5: =G5-H5-C5 -> 2200 | J5: =I5+M5 -> 2200 | K5: =P5+S5+V5+Y5+AB5+AE5+AH5+AK5+AN5+AQ5+AT5+AW5 -> 1.78 | L5: =(H5-K5-C5)*5.5% -> 5.4021 | M5: 0 | N5: =H5-K5-M5+L5 -> 203.6221 | O5: 0 | P5: =O5*0.89% -> 0 | Q5: 0 | R5: ='2018-2019 B STATEMENT '!B7 -> 200 | S5: =R5*0.89% -> 1.78 | T5: 0 | U5: 0 | V5: =U5*0.89% -> 0 | W5: 0 | X5: 0 | Y5: =X5*0.89% -> 0 | Z5: 0 | AA5: 0 | AB5: =AA5*0.89% -> 0 | AC5: 0 | AD5: 0 | AE5: =AD5*0.89% -> 0 | AF5: 0 | AG5: 0 | AH5: =AG5*0.89% -> 0 | AI5: 0 | AJ5: 0 | AK5: =AJ5*0.89% -> 0 | AL5: 0 | AM5: 0 | AN5: =AM5*0.99% -> 0 | AO5: 0 | AP5: 0 | AQ5: =AP5*0.99% -> 0 | AR5: 0 | AS5: 0 | AT5: =AS5*0.99% -> 0 | AU5: 0 | AV5: 0 | AW5: =AV5*0.99% -> 0 | AX5: 0 | AY5: =O5+R5+U5+X5+AA5+AD5+AJ5+AG5+AM5+AP5+AS5+AV5 -> 200
A6: Member 5 | B6: 4/7/2018 | C6: 100 | D6: =200*12 -> 2400 | E6: 0 | F6: ='Catch up Fee'!D6 -> 0 | G6: =C6+D6 -> 2500 | H6: =AY6 -> 2500 | I6: =G6-H6-C6 -> -100 | J6: =I6+M6 -> -100 | K6: =P6+S6+V6+Y6+AB6+AE6+AH6+AK6+AN6+AQ6+AT6+AW6 -> 23.05 | L6: =(H6-K6-C6)*5.5% -> 130.73225 | M6: 0 | N6: =H6-K6-M6+L6 -> 2607.6822 | O6: 0 | P6: =O6*0.89% -> 0 | Q6: 0 | R6: ='2018-2019 B STATEMENT '!B10 -> 300 | S6: =R6*0.89% -> 2.67 | T6: 0 | U6: ='2018-2019 B STATEMENT '!B36+'2018-2019 B STATEMENT '!B65 -> 400 | V6: =U6*0.89% -> 3.56 | W6: 0 | X6: 0 | Y6: =X6*0.89% -> 0 | Z6: 0 | AA6: ='2018-2019 B STATEMENT '!B111 -> 200 | AB6: =AA6*0.89% -> 1.78 | AC6: 0 | AD6: ='2018-2019 B STATEMENT '!B154 -> 200 | AE6: =AD6*0.89% -> 1.78 | AF6: 0 | AG6: ='2018-2019 B STATEMENT '!B164+'2018-2019 B STATEMENT '!B165 -> 400 | AH6: =AG6*0.89% -> 3.56 | AI6: 0 | AJ6: ='2018-2019 B STATEMENT '!B190 -> 200 | AK6: =AJ6*0.89% -> 1.78 | AL6: 0 | AM6: ='2018-2019 B STATEMENT '!B217 -> 200 | AN6: =AM6*0.99% -> 1.98 | AO6: 0 | AP6: ='2018-2019 B STATEMENT '!B261 -> 200 | AQ6: =AP6*0.99% -> 1.98 | AR6: 0 | AS6: ='2018-2019 B STATEMENT '!B274 -> 200 | AT6: =AS6*0.99% -> 1.98 | AU6: 0 | AV6: ='2018-2019 B STATEMENT '!B300 -> 200 | AW6: =AV6*0.99% -> 1.98 | AX6: 0 | AY6: =O6+R6+U6+X6+AA6+AD6+AJ6+AG6+AM6+AP6+AS6+AV6 -> 2500
A7: Member 6 | B7: 14/10/2018 | C7: 100 | D7: =200*12 -> 2400 | E7: 0 | F7: ='Catch up Fee'!D7 -> 600 | G7: =C7+D7 -> 2500 | H7: =AY7 -> 1100 | I7: =G7-H7 -> 1400 | J7: =I7+M7 -> 1400 | K7: =P7+S7+V7+Y7+AB7+AE7+AH7+AK7+AN7+AQ7+AT7+AW7 -> 10.89 | L7: =(H7-K7-C7)*5.5% -> 54.40105 | M7: 0 | N7: =H7-K7-M7+L7 -> 1143.511 | O7: 0 | P7: =O7*0.89% -> 0 | Q7: 0 | R7: 0 | S7: =R7*0.89% -> 0 | T7: 0 | U7: 0 | V7: =U7*0.89% -> 0 | W7: 0 | X7: 0 | Y7: =X7*0.89% -> 0 | Z7: 0 | AA7: 0 | AB7: =AA7*0.89% -> 0 | AC7: 0 | AD7: 0 | AE7: =AD7*0.89% -> 0 | AF7: 0 | AG7: 0 | AH7: =AG7*0.89% -> 0 | AI7: 0 | AJ7: 0 | AK7: =AJ7*0.89% -> 0 | AL7: 0 | AM7: ='2018-2019 B STATEMENT '!B228 -> 300 | AN7: =AM7*0.99% -> 2.97 | AO7: 0 | AP7: ='2018-2019 B STATEMENT '!B252 -> 300 | AQ7: =AP7*0.99% -> 2.97 | AR7: 0 | AS7: ='2018-2019 B STATEMENT '!B271 -> 500 | AT7: =AS7*0.99% -> 4.95 | AU7: 0 | AV7: 0 | AW7: =AV7*0.99% -> 0 | AX7: 0 | AY7: =O7+R7+U7+X7+AA7+AD7+AJ7+AG7+AM7+AP7+AS7+AV7 -> 1100
A8: Member 7 | B8: 27/10/2021 | C8: 0 | D8: =200*12 -> 2400 | E8: 0 | F8: ='Catch up Fee'!D8 -> 7800 | G8: =C8+D8 -> 2400 | H8: =AY8 -> 0 | I8: =G8-H8 -> 2400 | J8: =I8+M8 -> 2400 | K8: =P8+S8+V8+Y8+AB8+AE8+AH8+AK8+AN8+AQ8+AT8+AW8 -> 0 | L8: =(H8-K8-C8)*5.5% -> 0 | M8: 0 | N8: =H8-K8-M8+L8 -> 0 | O8: 0 | P8: =O8*0.89% -> 0 | Q8: 0 | R8: 0 | S8: =R8*0.89% -> 0 | T8: 0 | U8: 0 | V8: =U8*0.89% -> 0 | W8: 0 | X8: 0 | Y8: =X8*0.89% -> 0 | Z8: 0 | AA8: 0 | AB8: =AA8*0.89% -> 0 | AC8: 0 | AD8: 0 | AE8: =AD8*0.89% -> 0 | AF8: 0 | AG8: 0 | AH8: =AG8*0.89% -> 0 | AI8: 0 | AJ8: 0 | AK8: =AJ8*0.89% -> 0 | AL8: 0 | AM8: 0 | AN8: =AM8*0.99% -> 0 | AO8: 0 | AP8: 0 | AQ8: =AP8*0.99% -> 0 | AR8: 0 | AS8: 0 | AT8: =AS8*0.99% -> 0 | AU8: 0 | AV8: 0 | AW8: =AV8*0.99% -> 0 | AX8: 0 | AY8: =O8+R8+U8+X8+AA8+AD8+AJ8+AG8+AM8+AP8+AS8+AV8 -> 0
A9: Member 8 | B9: 23/07/2018 | C9: 100 | D9: =200*12 -> 2400 | E9: 0 | F9: ='Catch up Fee'!D9 -> 0 | G9: =C9+D9 -> 2500 | H9: =AY9 -> 1300 | I9: =G9-H9-C9 -> 1100 | J9: =I9+M9 -> 1100 | K9: =P9+S9+V9+Y9+AB9+AE9+AH9+AK9+AN9+AQ9+AT9+AW9 -> 11.57 | L9: =(H9-K9-C9)*5.5% -> 65.36365 | M9: 0 | N9: =H9-K9-M9+L9 -> 1353.7937 | O9: 0 | P9: =O9*0.89% -> 0 | Q9: 0 | R9: ='2018-2019 B STATEMENT '!B13+'2018-2019 B STATEMENT '!B20 -> 500 | S9: =R9*0.89% -> 4.45 | T9: 0 | U9: 0 | V9: =U9*0.89% -> 0 | W9: 0 | X9: 0 | Y9: =X9*0.89% -> 0 | Z9: 0 | AA9: 0 | AB9: =AA9*0.89% -> 0 | AC9: 0 | AD9: 0 | AE9: =AD9*0.89% -> 0 | AF9: 0 | AG9: ='2018-2019 B STATEMENT '!B171 -> 400 | AH9: =AG9*0.89% -> 3.56 | AI9: 0 | AJ9: ='2018-2019 B STATEMENT '!B201 -> 400 | AK9: =AJ9*0.89% -> 3.56 | AL9: 0 | AM9: 0 | AN9: =AM9*0.99% -> 0 | AO9: 0 | AP9: 0 | AQ9: =AP9*0.99% -> 0 | AR9: 0 | AS9: 0 | AT9: =AS9*0.99% -> 0 | AU9: 0 | AV9: 0 | AW9: =AV9*0.99% -> 0 | AX9: 0 | AY9: =O9+R9+U9+X9+AA9+AD9+AJ9+AG9+AM9+AP9+AS9+AV9 -> 1300
A10: Member 9 | B10: 21/07/2018 | C10: 100 | D10: =200*12 -> 2400 | E10: 0 | F10: ='Catch up Fee'!D10 -> 0 | G10: =C10+D10 -> 2500 | H10: =AY10 -> 2100 | I10: =G10-H10-C10 -> 300 | J10: =I10+M10 -> 300 | K10: =P10+S10+V10+Y10+AB10+AE10+AH10+AK10+AN10+AQ10+AT10+AW10 -> 19.49 | L10: =(H10-K10-C10)*5.5% -> 108.92805 | M10: 0 | N10: =H10-K10-M10+L10 -> 2189.4381 | O10: 0 | P10: =O10*0.89% -> 0 | Q10: 0 | R10: ='2018-2019 B STATEMENT '!B21 -> 300 | S10: =R10*0.89% -> 2.67 | T10: 0 | U10: ='2018-2019 B STATEMENT '!B49 -> 200 | V10: =U10*0.89% -> 1.78 | W10: 0 | X10: ='2018-2019 B STATEMENT '!B96 -> 200 | Y10: =X10*0.89% -> 1.78 | Z10: 0 | AA10: ='2018-2019 B STATEMENT '!B121 -> 200 | AB10: =AA10*0.89% -> 1.78 | AC10: 0 | AD10: ='2018-2019 B STATEMENT '!B150 -> 200 | AE10: =AD10*0.89% -> 1.78 | AF10: 0 | AG10: 0 | AH10: =AG10*0.89% -> 0 | AI10: 0 | AJ10: ='2018-2019 B STATEMENT '!B191 -> 200 | AK10: =AJ10*0.89% -> 1.78 | AL10: 0 | AM10: ='2018-2019 B STATEMENT '!B221 -> 200 | AN10: =AM10*0.99% -> 1.98 | AO10: 0 | AP10: ='2018-2019 B STATEMENT '!B253 -> 200 | AQ10: =AP10*0.99% -> 1.98 | AR10: 0 | AS10: ='2018-2019 B STATEMENT '!B280 -> 200 | AT10: =AS10*0.99% -> 1.98 | AU10: 0 | AV10: ='2018-2019 B STATEMENT '!B304 -> 200 | AW10: =AV10*0.99% -> 1.98 | AX10: 0 | AY10: =O10+R10+U10+X10+AA10+AD10+AJ10+AG10+AM10+AP10+AS10+AV10 -> 2100
A11: Member 10 | B11: 30/06/2020 | C11: 0 | D11: =200*12 -> 2400 | E11: 0 | F11: ='Catch up Fee'!D11 -> 2400 | G11: =C11+D11 -> 2400 | H11: =AY11 -> 0 | I11: =G11-H11 -> 2400 | J11: =I11+M11 -> 2400 | K11: =P11+S11+V11+Y11+AB11+AE11+AH11+AK11+AN11+AQ11+AT11+AW11 -> 0 | L11: =(H11-K11-C11)*5.5% -> 0 | M11: 0 | N11: =H11-K11-M11+L11 -> 0 | O11: 0 | P11: =O11*0.89% -> 0 | Q11: 0 | R11: 0 | S11: =R11*0.89% -> 0 | T11: 0 | U11: 0 | V11: =U11*0.89% -> 0 | W11: 0 | X11: 0 | Y11: =X11*0.89% -> 0 | Z11: 0 | AA11: 0 | AB11: =AA11*0.89% -> 0 | AC11: 0 | AD11: 0 | AE11: =AD11*0.89% -> 0 | AF11: 0 | AG11: 0 | AH11: =AG11*0.89% -> 0 | AI11: 0 | AJ11: 0 | AK11: =AJ11*0.89% -> 0 | AL11: 0 | AM11: 0 | AN11: =AM11*0.99% -> 0 | AO11: 0 | AP11: 0 | AQ11: =AP11*0.99% -> 0 | AR11: 0 | AS11: 0 | AT11: =AS11*0.99% -> 0 | AU11: 0 | AV11: 0 | AW11: =AV11*0.99% -> 0 | AX11: 0 | AY11: =O11+R11+U11+X11+AA11+AD11+AJ11+AG11+AM11+AP11+AS11+AV11 -> 0
A12: Member 11 | B12: 15/08/2018 | C12: 100 | D12: =200*12 -> 2400 | E12: 0 | F12: ='Catch up Fee'!D12 -> 200 | G12: =C12+D12 -> 2500 | H12: =AY12 -> 3000 | I12: =G12-H12 -> -500 | J12: =I12+M12 -> -500 | K12: =P12+S12+V12+Y12+AB12+AE12+AH12+AK12+AN12+AQ12+AT12+AW12 -> 27.9 | L12: =(H12-K12-C12)*5.5% -> 157.9655 | M12: 0 | N12: =H12-K12-M12+L12 -> 3130.0655 | O12: 0 | P12: =O12*0.89% -> 0 | Q12: 0 | R12: 0 | S12: =R12*0.89% -> 0 | T12: 0 | U12: 0 | V12: =U12*0.89% -> 0 | W12: 0 | X12: 0 | Y12: =X12*0.89% -> 0 | Z12: 0 | AA12: ='2018-2019 B STATEMENT '!B115 -> 900 | AB12: =AA12*0.89% -> 8.01 | AC12: 0 | AD12: ='2018-2019 B STATEMENT '!B142 -> 300 | AE12: =AD12*0.89% -> 2.67 | AF12: 0 | AG12: 0 | AH12: =AG12*0.89% -> 0 | AI12: 0 | AJ12: ='2018-2019 B STATEMENT '!B188 -> 600 | AK12: =AJ12*0.89% -> 5.34 | AL12: 0 | AM12: ='2018-2019 B STATEMENT '!B236 -> 600 | AN12: =AM12*0.99% -> 5.94 | AO12: 0 | AP12: 0 | AQ12: =AP12*0.99% -> 0 | AR12: 0 | AS12: 0 | AT12: =AS12*0.99% -> 0 | AU12: 0 | AV12: ='2018-2019 B STATEMENT '!B296 -> 600 | AW12: =AV12*0.99% -> 5.94 | AX12: 0 | AY12: =O12+R12+U12+X12+AA12+AD12+AJ12+AG12+AM12+AP12+AS12+AV12 -> 3000
A13: Member 12 | B13: 3/7/2018 | C13: 100 | D13: =200*12 -> 2400 | E13: 0 | F13: ='Catch up Fee'!D13 -> 0 | G13: =C13+D13 -> 2500 | H13: =AY13 -> 2300 | I13: =G13-H13-C13 -> 100 | J13: =I13+M13 -> 100 | K13: =P13+S13+V13+Y13+AB13+AE13+AH13+AK13+AN13+AQ13+AT13+AW13 -> 21.27 | L13: =(H13-K13-C13)*5.5% -> 119.83015 | M13: 0 | N13: =H13-K13-M13+L13 -> 2398.5602 | O13: 0 | P13: =O13*0.89% -> 0 | Q13: 0 | R13: ='2018-2019 B STATEMENT '!B17 -> 300 | S13: =R13*0.89% -> 2.67 | T13: 0 | U13: ='2018-2019 B STATEMENT '!B39 -> 200 | V13: =U13*0.89% -> 1.78 | W13: 0 | X13: ='2018-2019 B STATEMENT '!B92 -> 200 | Y13: =X13*0.89% -> 1.78 | Z13: 0 | AA13: ='2018-2019 B STATEMENT '!B112 -> 200 | AB13: =AA13*0.89% -> 1.78 | AC13: 0 | AD13: ='2018-2019 B STATEMENT '!B143 -> 200 | AE13: =AD13*0.89% -> 1.78 | AF13: 0 | AG13: ='2018-2019 B STATEMENT '!B166 -> 200 | AH13: =AG13*0.89% -> 1.78 | AI13: 0 | AJ13: ='2018-2019 B STATEMENT '!B184 -> 200 | AK13: =AJ13*0.89% -> 1.78 | AL13: 0 | AM13: ='2018-2019 B STATEMENT '!B210 -> 200 | AN13: =AM13*0.99% -> 1.98 | AO13: 0 | AP13: ='2018-2019 B STATEMENT '!B242 -> 200 | AQ13: =AP13*0.99% -> 1.98 | AR13: 0 | AS13: ='2018-2019 B STATEMENT '!B273 -> 200 | AT13: =AS13*0.99% -> 1.98 | AU13: 0 | AV13: ='2018-2019 B STATEMENT '!B297 -> 200 | AW13: =AV13*0.99% -> 1.98 | AX13: 0 | AY13: =O13+R13+U13+X13+AA13+AD13+AJ13+AG13+AM13+AP13+AS13+AV13 -> 2300
A14: Member 13 | B14: 28/07/2018 | C14: 100 | D14: =200*12 -> 2400 | E14: 0 | F14: ='Catch up Fee'!D14 -> 0 | G14: =C14+D14 -> 2500 | H14: =AY14 -> 2100 | I14: =G14-H14-C14 -> 300 | J14: =I14+M14 -> 300 | K14: =P14+S14+V14+Y14+AB14+AE14+AH14+AK14+AN14+AQ14+AT14+AW14 -> 19.29 | L14: =(H14-K14-C14)*5.5% -> 108.93905 | M14: 0 | N14: =H14-K14-M14+L14 -> 2189.649 | O14: 0 | P14: =O14*0.89% -> 0 | Q14: 0 | R14: ='2018-2019 B STATEMENT '!B22 -> 300 | S14: =R14*0.89% -> 2.67 | T14: 0 | U14: 0 | V14: =U14*0.89% -> 0 | W14: 0 | X14: ='2018-2019 B STATEMENT '!B72 -> 600 | Y14: =X14*0.89% -> 5.34 | Z14: 0 | AA14: 0 | AB14: =AA14*0.89% -> 0 | AC14: 0 | AD14: 0 | AE14: =AD14*0.89% -> 0 | AF14: 0 | AG14: 0 | AH14: =AG14*0.89% -> 0 | AI14: 0 | AJ14: ='2018-2019 B STATEMENT '!B186 -> 600 | AK14: =AJ14*0.89% -> 5.34 | AL14: 0 | AM14: 0 | AN14: =AM14*0.99% -> 0 | AO14: 0 | AP14: 0 | AQ14: =AP14*0.99% -> 0 | AR14: 0 | AS14: ='2018-2019 B STATEMENT '!B286 -> 600 | AT14: =AS14*0.99% -> 5.94 | AU14: 0 | AV14: 0 | AW14: =AV14*0.99% -> 0 | AX14: 0 | AY14: =O14+R14+U14+X14+AA14+AD14+AJ14+AG14+AM14+AP14+AS14+AV14 -> 2100
A15: Member 14 | B15: 3/7/2018 | C15: 100 | D15: =200*12 -> 2400 | E15: 0 | F15: ='Catch up Fee'!D15 -> 0 | G15: =C15+D15 -> 2500 | H15: =AY15 -> 100 | I15: =G15-H15-C15 -> 2300 | J15: =I15+M15 -> 2300 | K15: =P15+S15+V15+Y15+AB15+AE15+AH15+AK15+AN15+AQ15+AT15+AW15 -> 0.89 | L15: =(H15-K15-C15)*5.5% -> -0.04895 | M15: 0 | N15: =H15-K15-M15+L15 -> 99.06105 | O15: 0 | P15: =O15*0.89% -> 0 | Q15: 0 | R15: ='2018-2019 B STATEMENT '!B3 -> 100 | S15: =R15*0.89% -> 0.89 | T15: 0 | U15: 0 | V15: =U15*0.89% -> 0 | W15: 0 | X15: 0 | Y15: =X15*0.89% -> 0 | Z15: 0 | AA15: 0 | AB15: =AA15*0.89% -> 0 | AC15: 0 | AD15: 0 | AE15: =AD15*0.89% -> 0 | AF15: 0 | AG15: 0 | AH15: =AG15*0.89% -> 0 | AI15: 0 | AJ15: 0 | AK15: =AJ15*0.89% -> 0 | AL15: 0 | AM15: 0 | AN15: =AM15*0.99% -> 0 | AO15: 0 | AP15: 0 | AQ15: =AP15*0.99% -> 0 | AR15: 0 | AS15: 0 | AT15: =AS15*0.99% -> 0 | AU15: 0 | AV15: 0 | AW15: =AV15*0.99% -> 0 | AX15: 0 | AY15: =O15+R15+U15+X15+AA15+AD15+AJ15+AG15+AM15+AP15+AS15+AV15 -> 100
A16: Member 15 | C16: 100 | D16: =200*12 -> 2400 | E16: 0 | F16: ='Catch up Fee'!D16 -> 0 | G16: =C16+D16 -> 2500 | H16: =AY16 -> 0 | I16: =G16-H16-C16 -> 2400 | J16: =I16+M16 -> 2400 | K16: =P16+S16+V16+Y16+AB16+AE16+AH16+AK16+AN16+AQ16+AT16+AW16 -> 0 | L16: =(H16-K16-C16)*5.5% -> -5.5 | M16: 0 | N16: =H16-K16-M16+L16 -> -5.5 | O16: 0 | P16: =O16*0.89% -> 0 | Q16: 0 | R16: 0 | S16: =R16*0.89% -> 0 | T16: 0 | U16: 0 | V16: =U16*0.89% -> 0 | W16: 0 | X16: 0 | Y16: =X16*0.89% -> 0 | Z16: 0 | AA16: 0 | AB16: =AA16*0.89% -> 0 | AC16: 0 | AD16: 0 | AE16: =AD16*0.89% -> 0 | AF16: 0 | AG16: 0 | AH16: =AG16*0.89% -> 0 | AI16: 0 | AJ16: 0 | AK16: =AJ16*0.89% -> 0 | AL16: 0 | AM16: 0 | AN16: =AM16*0.99% -> 0 | AO16: 0 | AP16: 0 | AQ16: =AP16*0.99% -> 0 | AR16: 0 | AS16: 0 | AT16: =AS16*0.99% -> 0 | AU16: 0 | AV16: 0 | AW16: =AV16*0.99% -> 0 | AX16: 0 | AY16: =O16+R16+U16+X16+AA16+AD16+AJ16+AG16+AM16+AP16+AS16+AV16 -> 0
A17: Member 16 | B17: 28/07/2018 | C17: 100 | D17: =200*12 -> 2400 | E17: 0 | F17: ='Catch up Fee'!D17 -> 0 | G17: =C17+D17 -> 2500 | H17: =AY17 -> 1300 | I17: =G17-H17-C17 -> 1100 | J17: =I17+M17 -> 1100 | K17: =P17+S17+V17+Y17+AB17+AE17+AH17+AK17+AN17+AQ17+AT17+AW17 -> 11.97 | L17: =(H17-K17-C17)*5.5% -> 65.34165 | M17: 0 | N17: =H17-K17-M17+L17 -> 1353.3717 | O17: 0 | P17: =O17*0.89% -> 0 | Q17: 0 | R17: 0 | S17: =R17*0.89% -> 0 | T17: 0 | U17: ='2018-2019 B STATEMENT '!B34+'2018-2019 B STATEMENT '!B64 -> 500 | V17: =U17*0.89% -> 4.45 | W17: 0 | X17: 0 | Y17: =X17*0.89% -> 0 | Z17: 0 | AA17: ='2018-2019 B STATEMENT '!B135 -> 200 | AB17: =AA17*0.89% -> 1.78 | AC17: 0 | AD17: 0 | AE17: =AD17*0.89% -> 0 | AF17: 0 | AG17: ='2018-2019 B STATEMENT '!B174 -> 200 | AH17: =AG17*0.89% -> 1.78 | AI17: 0 | AJ17: 0 | AK17: =AJ17*0.89% -> 0 | AL17: 0 | AM17: ='2018-2019 B STATEMENT '!B206 -> 200 | AN17: =AM17*0.99% -> 1.98 | AO17: 0 | AP17: 0 | AQ17: =AP17*0.99% -> 0 | AR17: 0 | AS17: 0 | AT17: =AS17*0.99% -> 0 | AU17: 0 | AV17: ='2018-2019 B STATEMENT '!B315 -> 200 | AW17: =AV17*0.99% -> 1.98 | AX17: 0 | AY17: =O17+R17+U17+X17+AA17+AD17+AJ17+AG17+AM17+AP17+AS17+AV17 -> 1300
A18: Member 17 | B18: 25/01/2019 | C18: 100 | D18: =200*12 -> 2400 | E18: 0 | F18: ='Catch up Fee'!D18 -> 1200 | G18: =C18+D18 -> 2500 | H18: =AY18 -> 2350 | I18: =G18-H18 -> 150 | J18: =I18+M18 -> 150 | K18: =P18+S18+V18+Y18+AB18+AE18+AH18+AK18+AN18+AQ18+AT18+AW18 -> 22.915 | L18: =(H18-K18-C18)*5.5% -> 122.48968 | M18: 0 | N18: =H18-K18-M18+L18 -> 2449.5747 | O18: 0 | P18: =O18*0.89% -> 0 | Q18: 0 | R18: 0 | S18: =R18*0.89% -> 0 | T18: 0 | U18: 0 | V18: =U18*0.89% -> 0 | W18: 0 | X18: 0 | Y18: =X18*0.89% -> 0 | Z18: 0 | AA18: 0 | AB18: =AA18*0.89% -> 0 | AC18: 0 | AD18: 0 | AE18: =AD18*0.89% -> 0 | AF18: 0 | AG18: 0 | AH18: =AG18*0.89% -> 0 | AI18: 0 | AJ18: ='2018-2019 B STATEMENT '!B192 -> 350 | AK18: =AJ18*0.89% -> 3.115 | AL18: 0 | AM18: ='2018-2019 B STATEMENT '!B211 -> 1500 | AN18: =AM18*0.99% -> 14.85 | AO18: 0 | AP18: ='2018-2019 B STATEMENT '!B243 -> 500 | AQ18: =AP18*0.99% -> 4.95 | AR18: 0 | AS18: 0 | AT18: =AS18*0.99% -> 0 | AU18: 0 | AV18: 0 | AW18: =AV18*0.99% -> 0 | AX18: 0 | AY18: =O18+R18+U18+X18+AA18+AD18+AJ18+AG18+AM18+AP18+AS18+AV18 -> 2350
A19: Member 18 | B19: 3/7/2018 | C19: 100 | D19: =200*12 -> 2400 | E19: 0 | F19: ='Catch up Fee'!D19 -> 0 | G19: =C19+D19 -> 2500 | H19: =AY19 -> 2300 | I19: =G19-H19-C19 -> 100 | J19: =I19+M19 -> 100 | K19: =P19+S19+V19+Y19+AB19+AE19+AH19+AK19+AN19+AQ19+AT19+AW19 -> 21.27 | L19: =(H19-K19-C19)*5.5% -> 119.83015 | M19: 0 | N19: =H19-K19-M19+L19 -> 2398.5602 | O19: 0 | P19: =O19*0.89% -> 0 | Q19: 0 | R19: ='2018-2019 B STATEMENT '!B14 -> 300 | S19: =R19*0.89% -> 2.67 | T19: 0 | U19: ='2018-2019 B STATEMENT '!B46 -> 200 | V19: =U19*0.89% -> 1.78 | W19: 0 | X19: ='2018-2019 B STATEMENT '!B88 -> 200 | Y19: =X19*0.89% -> 1.78 | Z19: 0 | AA19: ='2018-2019 B STATEMENT '!B116 -> 200 | AB19: =AA19*0.89% -> 1.78 | AC19: 0 | AD19: ='2018-2019 B STATEMENT '!B147 -> 200 | AE19: =AD19*0.89% -> 1.78 | AF19: 0 | AG19: ='2018-2019 B STATEMENT '!B175 -> 200 | AH19: =AG19*0.89% -> 1.78 | AI19: 0 | AJ19: ='2018-2019 B STATEMENT '!B189 -> 200 | AK19: =AJ19*0.89% -> 1.78 | AL19: 0 | AM19: ='2018-2019 B STATEMENT '!B213 -> 200 | AN19: =AM19*0.99% -> 1.98 | AO19: 0 | AP19: ='2018-2019 B STATEMENT '!B247 -> 200 | AQ19: =AP19*0.99% -> 1.98 | AR19: 0 | AS19: ='2018-2019 B STATEMENT '!B275 -> 200 | AT19: =AS19*0.99% -> 1.98 | AU19: 0 | AV19: ='2018-2019 B STATEMENT '!B301 -> 200 | AW19: =AV19*0.99% -> 1.98 | AX19: 0 | AY19: =O19+R19+U19+X19+AA19+AD19+AJ19+AG19+AM19+AP19+AS19+AV19 -> 2300
A20: Member 19 | B20: 16/7/2019 | C20: 0 | D20: =200*12 -> 2400 | E20: 0 | F20: ='Catch up Fee'!D20 -> 2400 | G20: =C20+D20 -> 2400 | H20: =AY20 -> 0 | I20: =G20-H20 -> 2400 | J20: =I20+M20 -> 2400 | K20: =P20+S20+V20+Y20+AB20+AE20+AH20+AK20+AN20+AQ20+AT20+AW20 -> 0 | L20: =(H20-K20-C20)*5.5% -> 0 | M20: 0 | N20: =H20-K20-M20+L20 -> 0 | O20: 0 | P20: =O20*0.89% -> 0 | Q20: 0 | R20: 0 | S20: =R20*0.89% -> 0 | T20: 0 | U20: 0 | V20: =U20*0.89% -> 0 | W20: 0 | X20: 0 | Y20: =X20*0.89% -> 0 | Z20: 0 | AA20: 0 | AB20: =AA20*0.89% -> 0 | AC20: 0 | AD20: 0 | AE20: =AD20*0.89% -> 0 | AF20: 0 | AG20: 0 | AH20: =AG20*0.89% -> 0 | AI20: 0 | AJ20: 0 | AK20: =AJ20*0.89% -> 0 | AL20: 0 | AM20: 0 | AN20: =AM20*0.99% -> 0 | AO20: 0 | AP20: 0 | AQ20: =AP20*0.99% -> 0 | AR20: 0 | AS20: 0 | AT20: =AS20*0.99% -> 0 | AU20: 0 | AV20: 0 | AW20: =AV20*0.99% -> 0 | AX20: 0 | AY20: =O20+R20+U20+X20+AA20+AD20+AJ20+AG20+AM20+AP20+AS20+AV20 -> 0
A21: Member 20 | B21: 25/07/2018 | C21: 100 | D21: =200*12 -> 2400 | E21: 0 | F21: ='Catch up Fee'!D21 -> 0 | G21: =C21+D21 -> 2500 | H21: =AY21 -> 900 | I21: =G21-H21-C21 -> 1500 | J21: =I21+M21 -> 1500 | K21: =P21+S21+V21+Y21+AB21+AE21+AH21+AK21+AN21+AQ21+AT21+AW21 -> 8.01 | L21: =(H21-K21-C21)*5.5% -> 43.55945 | M21: 0 | N21: =H21-K21-M21+L21 -> 935.54945 | O21: 0 | P21: =O21*0.89% -> 0 | Q21: 0 | R21: ='2018-2019 B STATEMENT '!B28 -> 300 | S21: =R21*0.89% -> 2.67 | T21: 0 | U21: 0 | V21: =U21*0.89% -> 0 | W21: 0 | X21: ='2018-2019 B STATEMENT '!B76 -> 200 | Y21: =X21*0.89% -> 1.78 | Z21: 0 | AA21: 0 | AB21: =AA21*0.89% -> 0 | AC21: 0 | AD21: 0 | AE21: =AD21*0.89% -> 0 | AF21: 0 | AG21: ='2018-2019 B STATEMENT '!B176 -> 400 | AH21: =AG21*0.89% -> 3.56 | AI21: 0 | AJ21: 0 | AK21: =AJ21*0.89% -> 0 | AL21: 0 | AM21: 0 | AN21: =AM21*0.99% -> 0 | AO21: 0 | AP21: 0 | AQ21: =AP21*0.99% -> 0 | AR21: 0 | AS21: 0 | AT21: =AS21*0.99% -> 0 | AU21: 0 | AV21: 0 | AW21: =AV21*0.99% -> 0 | AX21: 0 | AY21: =O21+R21+U21+X21+AA21+AD21+AJ21+AG21+AM21+AP21+AS21+AV21 -> 900
A22: Member 21 | B22: 20/08/2018 | C22: 100 | D22: =200*12 -> 2400 | E22: 0 | F22: ='Catch up Fee'!D22 -> 200 | G22: =C22+D22 -> 2500 | H22: =AY22 -> 1300 | I22: =G22-H22 -> 1200 | J22: =I22+M22 -> 1200 | K22: =P22+S22+V22+Y22+AB22+AE22+AH22+AK22+AN22+AQ22+AT22+AW22 -> 11.97 | L22: =(H22-K22-C22)*5.5% -> 65.34165 | M22: 0 | N22: =H22-K22-M22+L22 -> 1353.3717 | O22: 0 | P22: =O22*0.89% -> 0 | Q22: 0 | R22: 0 | S22: =R22*0.89% -> 0 | T22: 0 | U22: ='2018-2019 B STATEMENT '!B71 -> 300 | V22: =U22*0.89% -> 2.67 | W22: 0 | X22: ='2018-2019 B STATEMENT '!B87 -> 400 | Y22: =X22*0.89% -> 3.56 | Z22: 0 | AA22: ='2018-2019 B STATEMENT '!B133 -> 200 | AB22: =AA22*0.89% -> 1.78 | AC22: 0 | AD22: 0 | AE22: =AD22*0.89% -> 0 | AF22: 0 | AG22: 0 | AH22: =AG22*0.89% -> 0 | AI22: 0 | AJ22: 0 | AK22: =AJ22*0.89% -> 0 | AL22: 0 | AM22: 0 | AN22: =AM22*0.99% -> 0 | AO22: 0 | AP22: ='2018-2019 B STATEMENT '!B259+'2018-2019 B STATEMENT '!B268 -> 400 | AQ22: =AP22*0.99% -> 3.96 | AR22: 0 | AS22: 0 | AT22: =AS22*0.99% -> 0 | AU22: 0 | AV22: 0 | AW22: =AV22*0.99% -> 0 | AX22: 0 | AY22: =O22+R22+U22+X22+AA22+AD22+AJ22+AG22+AM22+AP22+AS22+AV22 -> 1300
A23: Member 22 | B23: 26/08/2018 | C23: 100 | D23: =200*12 -> 2400 | E23: 0 | F23: ='Catch up Fee'!D23 -> 200 | G23: =C23+D23 -> 2500 | H23: =AY23 -> 2800 | I23: =G23-H23 -> -300 | J23: =I23+M23 -> -300 | K23: =P23+S23+V23+Y23+AB23+AE23+AH23+AK23+AN23+AQ23+AT23+AW23 -> 26.12 | L23: =(H23-K23-C23)*5.5% -> 147.0634 | M23: 0 | N23: =H23-K23-M23+L23 -> 2920.9434 | O23: 0 | P23: =O23*0.89% -> 0 | Q23: 0 | R23: 0 | S23: =R23*0.89% -> 0 | T23: 0 | U23: 0 | V23: =U23*0.89% -> 0 | W23: 0 | X23: ='2018-2019 B STATEMENT '!B85 -> 500 | Y23: =X23*0.89% -> 4.45 | Z23: 0 | AA23: ='2018-2019 B STATEMENT '!B113+'2018-2019 B STATEMENT '!B128 -> 500 | AB23: =AA23*0.89% -> 4.45 | AC23: 0 | AD23: 0 | AE23: =AD23*0.89% -> 0 | AF23: 0 | AG23: ='2018-2019 B STATEMENT '!B177 -> 200 | AH23: =AG23*0.89% -> 1.78 | AI23: 0 | AJ23: ='2018-2019 B STATEMENT '!B205 -> 400 | AK23: =AJ23*0.89% -> 3.56 | AL23: 0 | AM23: 0 | AN23: =AM23*0.99% -> 0 | AO23: 0 | AP23: ='2018-2019 B STATEMENT '!B262 -> 400 | AQ23: =AP23*0.99% -> 3.96 | AR23: 0 | AS23: ='2018-2019 B STATEMENT '!B295 -> 400 | AT23: =AS23*0.99% -> 3.96 | AU23: 0 | AV23: ='2018-2019 B STATEMENT '!B316 -> 400 | AW23: =AV23*0.99% -> 3.96 | AX23: 0 | AY23: =O23+R23+U23+X23+AA23+AD23+AJ23+AG23+AM23+AP23+AS23+AV23 -> 2800
A24: Member 23 | B24: 3/7/2018 | C24: 100 | D24: =200*12 -> 2400 | E24: 0 | F24: ='Catch up Fee'!D24 -> 0 | G24: =C24+D24 -> 2500 | H24: =AY24 -> 500 | I24: =G24-H24-C24 -> 1900 | J24: =I24+M24 -> 1900 | K24: =P24+S24+V24+Y24+AB24+AE24+AH24+AK24+AN24+AQ24+AT24+AW24 -> 4.45 | L24: =(H24-K24-C24)*5.5% -> 21.75525 | M24: 0 | N24: =H24-K24-M24+L24 -> 517.30525 | O24: 0 | P24: =O24*0.89% -> 0 | Q24: 0 | R24: ='2018-2019 B STATEMENT '!B23 -> 300 | S24: =R24*0.89% -> 2.67 | T24: 0 | U24: 0 | V24: =U24*0.89% -> 0 | W24: 0 | X24: ='2018-2019 B STATEMENT '!B77 -> 200 | Y24: =X24*0.89% -> 1.78 | Z24: 0 | AA24: 0 | AB24: =AA24*0.89% -> 0 | AC24: 0 | AD24: 0 | AE24: =AD24*0.89% -> 0 | AF24: 0 | AG24: 0 | AH24: =AG24*0.89% -> 0 | AI24: 0 | AJ24: 0 | AK24: =AJ24*0.89% -> 0 | AL24: 0 | AM24: 0 | AN24: =AM24*0.99% -> 0 | AO24: 0 | AP24: 0 | AQ24: =AP24*0.99% -> 0 | AR24: 0 | AS24: 0 | AT24: =AS24*0.99% -> 0 | AU24: 0 | AV24: 0 | AW24: =AV24*0.99% -> 0 | AX24: 0 | AY24: =O24+R24+U24+X24+AA24+AD24+AJ24+AG24+AM24+AP24+AS24+AV24 -> 500
A25: Member 24 | B25: 27/08/2018 | C25: 100 | D25: =200*12 -> 2400 | E25: 0 | F25: ='Catch up Fee'!D25 -> 200 | G25: =C25+D25 -> 2500 | H25: =AY25 -> 0 | I25: =G25-H25 -> 2500 | J25: =I25+M25 -> 2500 | K25: =P25+S25+V25+Y25+AB25+AE25+AH25+AK25+AN25+AQ25+AT25+AW25 -> 0 | L25: =(H25-K25-C25)*5.5% -> -5.5 | M25: 0 | N25: =H25-K25-M25+L25 -> -5.5 | O25: 0 | P25: =O25*0.89% -> 0 | Q25: 0 | R25: 0 | S25: =R25*0.89% -> 0 | T25: 0 | U25: 0 | V25: =U25*0.89% -> 0 | W25: 0 | X25: 0 | Y25: =X25*0.89% -> 0 | Z25: 0 | AA25: 0 | AB25: =AA25*0.89% -> 0 | AC25: 0 | AD25: 0 | AE25: =AD25*0.89% -> 0 | AF25: 0 | AG25: 0 | AH25: =AG25*0.89% -> 0 | AI25: 0 | AJ25: 0 | AK25: =AJ25*0.89% -> 0 | AL25: 0 | AM25: 0 | AN25: =AM25*0.99% -> 0 | AO25: 0 | AP25: 0 | AQ25: =AP25*0.99% -> 0 | AR25: 0 | AS25: 0 | AT25: =AS25*0.99% -> 0 | AU25: 0 | AV25: 0 | AW25: =AV25*0.99% -> 0 | AX25: 0 | AY25: =O25+R25+U25+X25+AA25+AD25+AJ25+AG25+AM25+AP25+AS25+AV25 -> 0
A26: Member 25 | B26: 29/06/2018 | C26: 100 | D26: =200*12 -> 2400 | E26: 0 | F26: ='Catch up Fee'!D26 -> 0 | G26: =C26+D26 -> 2500 | H26: =AY26 -> 1950 | I26: =G26-H26-C26 -> 450 | J26: =I26+M26 -> 450 | K26: =P26+S26+V26+Y26+AB26+AE26+AH26+AK26+AN26+AQ26+AT26+AW26 -> 17.755 | L26: =(H26-K26-C26)*5.5% -> 100.77347 | M26: 0 | N26: =H26-K26-M26+L26 -> 2033.0185 | O26: ='2018-2019 B STATEMENT '!B2 -> 150 | P26: =O26*0.89% -> 1.335 | Q26: 0 | R26: ='2018-2019 B STATEMENT '!B11 -> 200 | S26: =R26*0.89% -> 1.78 | T26: 0 | V26: =U26*0.89% -> 0 | W26: 0 | X26: ='2018-2019 B STATEMENT '!B73+'2018-2019 B STATEMENT '!B78 -> 1200 | Y26: =X26*0.89% -> 10.68 | Z26: 0 | AA26: 0 | AB26: =AA26*0.89% -> 0 | AC26: 0 | AD26: 0 | AE26: =AD26*0.89% -> 0 | AF26: 0 | AG26: 0 | AH26: =AG26*0.89% -> 0 | AI26: 0 | AJ26: 0 | AK26: =AJ26*0.89% -> 0 | AL26: 0 | AM26: 0 | AN26: =AM26*0.99% -> 0 | AO26: 0 | AP26: 0 | AQ26: =AP26*0.99% -> 0 | AR26: 0 | AS26: ='2018-2019 B STATEMENT '!B290 -> 400 | AT26: =AS26*0.99% -> 3.96 | AU26: 0 | AV26: 0 | AW26: =AV26*0.99% -> 0 | AX26: 0 | AY26: =O26+R26+U26+X26+AA26+AD26+AJ26+AG26+AM26+AP26+AS26+AV26 -> 1950
A27: Member 26 | B27: 4/7/2018 | C27: 100 | D27: =200*12 -> 2400 | E27: 0 | F27: ='Catch up Fee'!D27 -> 0 | G27: =C27+D27 -> 2500 | H27: =AY27 -> 700 | I27: =G27-H27-C27 -> 1700 | J27: =I27+M27 -> 1700 | K27: =P27+S27+V27+Y27+AB27+AE27+AH27+AK27+AN27+AQ27+AT27+AW27 -> 6.23 | L27: =(H27-K27-C27)*5.5% -> 32.65735 | M27: 0 | N27: =H27-K27-M27+L27 -> 726.42735 | O27: 0 | P27: =O27*0.89% -> 0 | Q27: 0 | R27: ='2018-2019 B STATEMENT '!B5+'2018-2019 B STATEMENT '!B30 -> 500 | S27: =R27*0.89% -> 4.45 | T27: 0 | U27: 0 | V27: =U27*0.89% -> 0 | W27: 0 | X27: 0 | Y27: =X27*0.89% -> 0 | Z27: 0 | AA27: ='2018-2019 B STATEMENT '!B134 -> 200 | AB27: =AA27*0.89% -> 1.78 | AC27: 0 | AD27: 0 | AE27: =AD27*0.89% -> 0 | AF27: 0 | AG27: 0 | AH27: =AG27*0.89% -> 0 | AI27: 0 | AJ27: 0 | AK27: =AJ27*0.89% -> 0 | AL27: 0 | AM27: 0 | AN27: =AM27*0.99% -> 0 | AO27: 0 | AP27: 0 | AQ27: =AP27*0.99% -> 0 | AR27: 0 | AS27: 0 | AT27: =AS27*0.99% -> 0 | AU27: 0 | AV27: 0 | AW27: =AV27*0.99% -> 0 | AX27: 0 | AY27: =O27+R27+U27+X27+AA27+AD27+AJ27+AG27+AM27+AP27+AS27+AV27 -> 700
A28: Member 27 | B28: 3/7/2018 | C28: 100 | D28: =200*12 -> 2400 | E28: 0 | F28: ='Catch up Fee'!D28 -> 0 | G28: =C28+D28 -> 2500 | H28: =AY28 -> 0 | I28: =G28-H28-C28 -> 2400 | J28: =I28+M28 -> 2400 | K28: =P28+S28+V28+Y28+AB28+AE28+AH28+AK28+AN28+AQ28+AT28+AW28 -> 0 | L28: =(H28-K28-C28)*5.5% -> -5.5 | M28: 0 | N28: =H28-K28-M28+L28 -> -5.5 | O28: 0 | P28: =O28*0.89% -> 0 | Q28: 0 | R28: 0 | S28: =R28*0.89% -> 0 | T28: 0 | U28: 0 | V28: =U28*0.89% -> 0 | W28: 0 | X28: 0 | Y28: =X28*0.89% -> 0 | Z28: 0 | AA28: 0 | AB28: =AA28*0.89% -> 0 | AC28: 0 | AD28: 0 | AE28: =AD28*0.89% -> 0 | AF28: 0 | AG28: 0 | AH28: =AG28*0.89% -> 0 | AI28: 0 | AJ28: 0 | AK28: =AJ28*0.89% -> 0 | AL28: 0 | AM28: 0 | AN28: =AM28*0.99% -> 0 | AO28: 0 | AP28: 0 | AQ28: =AP28*0.99% -> 0 | AR28: 0 | AS28: 0 | AT28: =AS28*0.99% -> 0 | AU28: 0 | AV28: 0 | AW28: =AV28*0.99% -> 0 | AX28: 0 | AY28: =O28+R28+U28+X28+AA28+AD28+AJ28+AG28+AM28+AP28+AS28+AV28 -> 0
A29: Member 28 | B29: 25/10/2019 | C29: 0 | D29: =200*12 -> 2400 | E29: 0 | F29: ='Catch up Fee'!D29 -> 3000 | G29: =C29+D29 -> 2400 | H29: =AY29 -> 500 | I29: =G29-H29 -> 1900 | J29: =I29+M29 -> 1900 | K29: =P29+S29+V29+Y29+AB29+AE29+AH29+AK29+AN29+AQ29+AT29+AW29 -> 4.45 | L29: =(H29-K29-C29)*5.5% -> 27.25525 | M29: 0 | N29: =H29-K29-M29+L29 -> 522.80525 | O29: 0 | P29: =O29*0.89% -> 0 | Q29: 0 | R29: 0 | S29: =R29*0.89% -> 0 | T29: 0 | U29: 0 | V29: =U29*0.89% -> 0 | W29: 0 | X29: 0 | Y29: =X29*0.89% -> 0 | Z29: 0 | AA29: 0 | AB29: =AA29*0.89% -> 0 | AC29: 0 | AD29: 500 | AE29: =AD29*0.89% -> 4.45 | AF29: 0 | AG29: 0 | AH29: =AG29*0.89% -> 0 | AI29: 0 | AJ29: 0 | AK29: =AJ29*0.89% -> 0 | AL29: 0 | AM29: 0 | AN29: =AM29*0.99% -> 0 | AO29: 0 | AP29: 0 | AQ29: =AP29*0.99% -> 0 | AR29: 0 | AS29: 0 | AT29: =AS29*0.99% -> 0 | AU29: 0 | AV29: 0 | AW29: =AV29*0.99% -> 0 | AX29: 0 | AY29: =O29+R29+U29+X29+AA29+AD29+AJ29+AG29+AM29+AP29+AS29+AV29 -> 500
A30: Member 29 | B30: 31/08/2018 | C30: 100 | D30: =200*12 -> 2400 | E30: 0 | F30: ='Catch up Fee'!D30 -> 200 | G30: =C30+D30 -> 2500 | H30: =AY30 -> 2100 | I30: =G30-H30 -> 400 | J30: =I30+M30 -> 400 | K30: =P30+S30+V30+Y30+AB30+AE30+AH30+AK30+AN30+AQ30+AT30+AW30 -> 20.19 | L30: =(H30-K30-C30)*5.5% -> 108.88955 | M30: 0 | N30: =H30-K30-M30+L30 -> 2188.6995 | O30: 0 | P30: =O30*0.89% -> 0 | Q30: 0 | R30: 0 | S30: =R30*0.89% -> 0 | T30: 0 | U30: 0 | V30: =U30*0.89% -> 0 | W30: 0 | X30: 0 | Y30: =X30*0.89% -> 0 | Z30: 0 | AA30: ='2018-2019 B STATEMENT '!B108+'2018-2019 B STATEMENT '!B109+'2018-2019 B STATEMENT '!B110 -> 600 | AB30: =AA30*0.89% -> 5.34 | AC30: 0 | AD30: 0 | AE30: =AD30*0.89% -> 0 | AF30: 0 | AG30: 0 | AH30: =AG30*0.89% -> 0 | AI30: 0 | AJ30: 0 | AK30: =AJ30*0.89% -> 0 | AL30: 0 | AM30: 0 | AN30: =AM30*0.99% -> 0 | AO30: 0 | AP30: 0 | AQ30: =AP30*0.99% -> 0 | AR30: 0 | AS30: ='2018-2019 B STATEMENT '!B269+'2018-2019 B STATEMENT '!B270 -> 1500 | AT30: =AS30*0.99% -> 14.85 | AU30: 0 | AV30: 0 | AW30: =AV30*0.99% -> 0 | AX30: 0 | AY30: =O30+R30+U30+X30+AA30+AD30+AJ30+AG30+AM30+AP30+AS30+AV30 -> 2100
A31: Member 30 | B31: 3/7/2018 | C31: 100 | D31: =200*12 -> 2400 | E31: 0 | F31: ='Catch up Fee'!D31 -> 0 | G31: =C31+D31 -> 2500 | H31: =AY31 -> 1700 | I31: =G31-H31-C31 -> 700 | J31: =I31+M31 -> 700 | K31: =P31+S31+V31+Y31+AB31+AE31+AH31+AK31+AN31+AQ31+AT31+AW31 -> 15.93 | L31: =(H31-K31-C31)*5.5% -> 87.12385 | M31: 0 | N31: =H31-K31-M31+L31 -> 1771.1938 | O31: 0 | P31: =O31*0.89% -> 0 | Q31: 0 | R31: ='2018-2019 B STATEMENT '!B8 -> 300 | S31: =R31*0.89% -> 2.67 | T31: 0 | U31: 0 | V31: =U31*0.89% -> 0 | W31: 0 | X31: ='2018-2019 B STATEMENT '!B83 -> 400 | Y31: =X31*0.89% -> 3.56 | Z31: 0 | AA31: 0 | AB31: =AA31*0.89% -> 0 | AC31: 0 | AD31: 0 | AE31: =AD31*0.89% -> 0 | AF31: 0 | AG31: ='2018-2019 B STATEMENT '!B178 -> 200 | AH31: =AG31*0.89% -> 1.78 | AI31: 0 | AJ31: 0 | AK31: =AJ31*0.89% -> 0 | AL31: 0 | AM31: ='2018-2019 B STATEMENT '!B218 -> 400 | AN31: =AM31*0.99% -> 3.96 | AO31: 0 | AP31: 0 | AQ31: =AP31*0.99% -> 0 | AR31: 0 | AS31: 0 | AT31: =AS31*0.99% -> 0 | AU31: 0 | AV31: ='2018-2019 B STATEMENT '!B312 -> 400 | AW31: =AV31*0.99% -> 3.96 | AX31: 0 | AY31: =O31+R31+U31+X31+AA31+AD31+AJ31+AG31+AM31+AP31+AS31+AV31 -> 1700
A32: Member 31 | B32: 28/07/2018 | C32: 100 | D32: =200*12 -> 2400 | E32: 0 | F32: ='Catch up Fee'!D32 -> 0 | G32: =C32+D32 -> 2500 | H32: =AY32 -> 500 | I32: =G32-H32-C32 -> 1900 | J32: =I32+M32 -> 1900 | K32: =P32+S32+V32+Y32+AB32+AE32+AH32+AK32+AN32+AQ32+AT32+AW32 -> 4.45 | L32: =(H32-K32-C32)*5.5% -> 21.75525 | M32: 0 | N32: =H32-K32-M32+L32 -> 517.30525 | O32: 0 | P32: =O32*0.89% -> 0 | Q32: 0 | R32: ='2018-2019 B STATEMENT '!B24 -> 300 | S32: =R32*0.89% -> 2.67 | T32: 0 | U32: ='2018-2019 B STATEMENT '!B37 -> 200 | V32: =U32*0.89% -> 1.78 | W32: 0 | X32: 0 | Y32: =X32*0.89% -> 0 | Z32: 0 | AA32: 0 | AB32: =AA32*0.89% -> 0 | AC32: 0 | AD32: 0 | AE32: =AD32*0.89% -> 0 | AF32: 0 | AG32: 0 | AH32: =AG32*0.89% -> 0 | AI32: 0 | AJ32: 0 | AK32: =AJ32*0.89% -> 0 | AL32: 0 | AM32: 0 | AN32: =AM32*0.99% -> 0 | AO32: 0 | AP32: 0 | AQ32: =AP32*0.99% -> 0 | AR32: 0 | AS32: 0 | AT32: =AS32*0.99% -> 0 | AU32: 0 | AV32: 0 | AW32: =AV32*0.99% -> 0 | AX32: 0 | AY32: =O32+R32+U32+X32+AA32+AD32+AJ32+AG32+AM32+AP32+AS32+AV32 -> 500
A33: Member 32 | B33: 22/08/2018 | C33: 100 | D33: =200*12 -> 2400 | E33: 0 | F33: ='Catch up Fee'!D33 -> 200 | G33: =C33+D33 -> 2500 | H33: =AY33 -> 1300 | I33: =G33-H33 -> 1200 | J33: =I33+M33 -> 1200 | K33: =P33+S33+V33+Y33+AB33+AE33+AH33+AK33+AN33+AQ33+AT33+AW33 -> 11.57 | L33: =(H33-K33-C33)*5.5% -> 65.36365 | M33: 0 | N33: =H33-K33-M33+L33 -> 1353.7937 | O33: 0 | P33: =O33*0.89% -> 0 | Q33: 0 | R33: 0 | S33: =R33*0.89% -> 0 | T33: 0 | U33: ='2018-2019 B STATEMENT '!B70 -> 500 | V33: =U33*0.89% -> 4.45 | W33: 0 | X33: ='2018-2019 B STATEMENT '!B104 -> 200 | Y33: =X33*0.89% -> 1.78 | Z33: 0 | AA33: ='2018-2019 B STATEMENT '!B136 -> 200 | AB33: =AA33*0.89% -> 1.78 | AC33: 0 | AD33: ='2018-2019 B STATEMENT '!B159 -> 400 | AE33: =AD33*0.89% -> 3.56 | AF33: 0 | AG33: 0 | AH33: =AG33*0.89% -> 0 | AI33: 0 | AJ33: 0 | AK33: =AJ33*0.89% -> 0 | AL33: 0 | AM33: 0 | AN33: =AM33*0.99% -> 0 | AO33: 0 | AP33: 0 | AQ33: =AP33*0.99% -> 0 | AR33: 0 | AS33: 0 | AT33: =AS33*0.99% -> 0 | AU33: 0 | AV33: 0 | AW33: =AV33*0.99% -> 0 | AX33: 0 | AY33: =O33+R33+U33+X33+AA33+AD33+AJ33+AG33+AM33+AP33+AS33+AV33 -> 1300
A34: Member 33 | C34: 100 | D34: =200*12 -> 2400 | E34: 0 | F34: ='Catch up Fee'!D34 -> 0 | G34: =C34+D34 -> 2500 | H34: =AY34 -> 0 | I34: =G34-H34-C34 -> 2400 | J34: =I34+M34 -> 2400 | K34: =P34+S34+V34+Y34+AB34+AE34+AH34+AK34+AN34+AQ34+AT34+AW34 -> 0 | L34: =(H34-K34-C34)*5.5% -> -5.5 | M34: 0 | N34: =H34-K34-M34+L34 -> -5.5 | O34: 0 | P34: =O34*0.89% -> 0 | Q34: 0 | R34: 0 | S34: =R34*0.89% -> 0 | T34: 0 | U34: 0 | V34: =U34*0.89% -> 0 | W34: 0 | X34: 0 | Y34: =X34*0.89% -> 0 | Z34: 0 | AA34: 0 | AB34: =AA34*0.89% -> 0 | AC34: 0 | AD34: 0 | AE34: =AD34*0.89% -> 0 | AF34: 0 | AG34: 0 | AH34: =AG34*0.89% -> 0 | AI34: 0 | AJ34: 0 | AK34: =AJ34*0.89% -> 0 | AL34: 0 | AM34: 0 | AN34: =AM34*0.99% -> 0 | AO34: 0 | AP34: 0 | AQ34: =AP34*0.99% -> 0 | AR34: 0 | AS34: 0 | AT34: =AS34*0.99% -> 0 | AU34: 0 | AV34: 0 | AW34: =AV34*0.99% -> 0 | AX34: 0 | AY34: =O34+R34+U34+X34+AA34+AD34+AJ34+AG34+AM34+AP34+AS34+AV34 -> 0
A35: Member 34 | B35: 15/08/2018 | C35: 100 | D35: =200*12 -> 2400 | E35: 0 | F35: ='Catch up Fee'!D35 -> 200 | G35: =C35+D35 -> 2500 | H35: =AY35 -> 500 | I35: =G35-H35 -> 2000 | J35: =I35+M35 -> 2000 | K35: =P35+S35+V35+Y35+AB35+AE35+AH35+AK35+AN35+AQ35+AT35+AW35 -> 4.45 | L35: =(H35-K35-C35)*5.5% -> 21.75525 | M35: 0 | N35: =H35-K35-M35+L35 -> 517.30525 | O35: 0 | P35: =O35*0.89% -> 0 | Q35: 0 | R35: 0 | S35: =R35*0.89% -> 0 | T35: 0 | U35: ='2018-2019 B STATEMENT '!B56 -> 300 | V35: =U35*0.89% -> 2.67 | W35: 0 | X35: 0 | Y35: =X35*0.89% -> 0 | Z35: 0 | AA35: ='2018-2019 B STATEMENT '!B129 -> 200 | AB35: =AA35*0.89% -> 1.78 | AC35: 0 | AD35: 0 | AE35: =AD35*0.89% -> 0 | AF35: 0 | AG35: 0 | AH35: =AG35*0.89% -> 0 | AI35: 0 | AJ35: 0 | AK35: =AJ35*0.89% -> 0 | AL35: 0 | AM35: 0 | AN35: =AM35*0.99% -> 0 | AO35: 0 | AP35: 0 | AQ35: =AP35*0.99% -> 0 | AR35: 0 | AS35: 0 | AT35: =AS35*0.99% -> 0 | AU35: 0 | AV35: 0 | AW35: =AV35*0.99% -> 0 | AX35: 0 | AY35: =O35+R35+U35+X35+AA35+AD35+AJ35+AG35+AM35+AP35+AS35+AV35 -> 500
A36: Member 35 | C36: 100 | D36: =200*12 -> 2400 | E36: 0 | F36: ='Catch up Fee'!D36 -> 0 | G36: =C36+D36 -> 2500 | H36: =AY36 -> 0 | I36: =G36-H36-C36 -> 2400 | J36: =I36+M36 -> 2400 | K36: =P36+S36+V36+Y36+AB36+AE36+AH36+AK36+AN36+AQ36+AT36+AW36 -> 0 | L36: =(H36-K36-C36)*5.5% -> -5.5 | M36: 0 | N36: =H36-K36-M36+L36 -> -5.5 | O36: 0 | P36: =O36*0.89% -> 0 | Q36: 0 | R36: 0 | S36: =R36*0.89% -> 0 | T36: 0 | U36: 0 | V36: =U36*0.89% -> 0 | W36: 0 | X36: 0 | Y36: =X36*0.89% -> 0 | Z36: 0 | AA36: 0 | AB36: =AA36*0.89% -> 0 | AC36: 0 | AD36: 0 | AE36: =AD36*0.89% -> 0 | AF36: 0 | AG36: 0 | AH36: =AG36*0.89% -> 0 | AI36: 0 | AJ36: 0 | AK36: =AJ36*0.89% -> 0 | AL36: 0 | AM36: 0 | AN36: =AM36*0.99% -> 0 | AO36: 0 | AP36: 0 | AQ36: =AP36*0.99% -> 0 | AR36: 0 | AS36: 0 | AT36: =AS36*0.99% -> 0 | AU36: 0 | AV36: 0 | AW36: =AV36*0.99% -> 0 | AX36: 0 | AY36: =O36+R36+U36+X36+AA36+AD36+AJ36+AG36+AM36+AP36+AS36+AV36 -> 0
A37: Member 36 | B37: 20/08/2019 | C37: 0 | D37: =200*12 -> 2400 | E37: 0 | F37: ='Catch up Fee'!D37 -> 2600 | G37: =C37+D37 -> 2400 | H37: =AY37 -> 0 | I37: =G37-H37 -> 2400 | J37: =I37+M37 -> 2400 | K37: =P37+S37+V37+Y37+AB37+AE37+AH37+AK37+AN37+AQ37+AT37+AW37 -> 0 | L37: =(H37-K37-C37)*5.5% -> 0 | M37: 0 | N37: =H37-K37-M37+L37 -> 0 | O37: 0 | P37: =O37*0.89% -> 0 | Q37: 0 | R37: 0 | S37: =R37*0.89% -> 0 | T37: 0 | U37: 0 | V37: =U37*0.89% -> 0 | W37: 0 | X37: 0 | Y37: =X37*0.89% -> 0 | Z37: 0 | AA37: 0 | AB37: =AA37*0.89% -> 0 | AC37: 0 | AD37: 0 | AE37: =AD37*0.89% -> 0 | AF37: 0 | AG37: 0 | AH37: =AG37*0.89% -> 0 | AI37: 0 | AJ37: 0 | AK37: =AJ37*0.89% -> 0 | AL37: 0 | AM37: 0 | AN37: =AM37*0.99% -> 0 | AO37: 0 | AP37: 0 | AQ37: =AP37*0.99% -> 0 | AR37: 0 | AS37: 0 | AT37: =AS37*0.99% -> 0 | AU37: 0 | AV37: 0 | AW37: =AV37*0.99% -> 0 | AX37: 0 | AY37: =O37+R37+U37+X37+AA37+AD37+AJ37+AG37+AM37+AP37+AS37+AV37 -> 0
A38: Member 37 | B38: 12/7/2018 | C38: 100 | D38: =200*12 -> 2400 | E38: 0 | F38: ='Catch up Fee'!D38 -> 0 | G38: =C38+D38 -> 2500 | H38: =AY38 -> 2300 | I38: =G38-H38-C38 -> 100 | J38: =I38+M38 -> 100 | K38: =P38+S38+V38+Y38+AB38+AE38+AH38+AK38+AN38+AQ38+AT38+AW38 -> 21.27 | L38: =(H38-K38-C38)*5.5% -> 119.83015 | M38: 0 | N38: =H38-K38-M38+L38 -> 2398.5602 | O38: 0 | P38: =O38*0.89% -> 0 | Q38: 0 | R38: ='2018-2019 B STATEMENT '!B12 -> 300 | S38: =R38*0.89% -> 2.67 | T38: 0 | U38: ='2018-2019 B STATEMENT '!B47 -> 200 | V38: =U38*0.89% -> 1.78 | W38: 0 | X38: ='2018-2019 B STATEMENT '!B89 -> 200 | Y38: =X38*0.89% -> 1.78 | Z38: 0 | AA38: ='2018-2019 B STATEMENT '!B118 -> 200 | AB38: =AA38*0.89% -> 1.78 | AC38: 0 | AD38: ='2018-2019 B STATEMENT '!B148 -> 400 | AE38: =AD38*0.89% -> 3.56 | AF38: 0 | AG38: 0 | AH38: =AG38*0.89% -> 0 | AI38: 0 | AJ38: ='2018-2019 B STATEMENT '!B193 -> 200 | AK38: =AJ38*0.89% -> 1.78 | AL38: 0 | AM38: ='2018-2019 B STATEMENT '!B214 -> 200 | AN38: =AM38*0.99% -> 1.98 | AO38: 0 | AP38: ='2018-2019 B STATEMENT '!B263 -> 400 | AQ38: =AP38*0.99% -> 3.96 | AR38: 0 | AS38: 0 | AT38: =AS38*0.99% -> 0 | AU38: 0 | AV38: ='2018-2019 B STATEMENT '!B313 -> 200 | AW38: =AV38*0.99% -> 1.98 | AX38: 0 | AY38: =O38+R38+U38+X38+AA38+AD38+AJ38+AG38+AM38+AP38+AS38+AV38 -> 2300
A39: Member 38 | B39: 16/7/2019 | C39: 0 | D39: =200*12 -> 2400 | E39: 0 | F39: ='Catch up Fee'!D39 -> 2400 | G39: =C39+D39 -> 2400 | H39: =AY39 -> 0 | I39: =G39-H39 -> 2400 | J39: =I39+M39 -> 2400 | K39: =P39+S39+V39+Y39+AB39+AE39+AH39+AK39+AN39+AQ39+AT39+AW39 -> 0 | L39: =(H39-K39-C39)*5.5% -> 0 | M39: 0 | N39: =H39-K39-M39+L39 -> 0 | O39: 0 | P39: =O39*0.89% -> 0 | Q39: 0 | R39: 0 | S39: =R39*0.89% -> 0 | T39: 0 | U39: 0 | V39: =U39*0.89% -> 0 | W39: 0 | X39: 0 | Y39: =X39*0.89% -> 0 | Z39: 0 | AA39: 0 | AB39: =AA39*0.89% -> 0 | AC39: 0 | AD39: 0 | AE39: =AD39*0.89% -> 0 | AF39: 0 | AG39: 0 | AH39: =AG39*0.89% -> 0 | AI39: 0 | AJ39: 0 | AK39: =AJ39*0.89% -> 0 | AL39: 0 | AM39: 0 | AN39: =AM39*0.99% -> 0 | AO39: 0 | AP39: 0 | AQ39: =AP39*0.99% -> 0 | AR39: 0 | AS39: 0 | AT39: =AS39*0.99% -> 0 | AU39: 0 | AV39: 0 | AW39: =AV39*0.99% -> 0 | AX39: 0 | AY39: =O39+R39+U39+X39+AA39+AD39+AJ39+AG39+AM39+AP39+AS39+AV39 -> 0
A40: Member 39 | B40: 25/08/2018 | C40: 100 | D40: =200*12 -> 2400 | E40: 0 | F40: ='Catch up Fee'!D40 -> 200 | G40: =C40+D40 -> 2500 | H40: =AY40 -> 2310 | I40: =G40-H40 -> 190 | J40: =I40+M40 -> 190 | K40: =P40+S40+V40+Y40+AB40+AE40+AH40+AK40+AN40+AQ40+AT40+AW40 -> 20.559 | L40: =(H40-K40-C40)*5.5% -> 120.41925 | M40: 0 | N40: =H40-K40-M40+L40 -> 2409.8603 | O40: 0 | P40: =O40*0.89% -> 0 | Q40: 0 | R40: ='2018-2019 B STATEMENT '!B18 -> 310 | S40: =R40*0.89% -> 2.759 | T40: 0 | U40: ='2018-2019 B STATEMENT '!B48 -> 1000 | V40: =U40*0.89% -> 8.9 | W40: 0 | X40: 0 | Y40: =X40*0.89% -> 0 | Z40: 0 | AA40: 0 | AB40: =AA40*0.89% -> 0 | AC40: 0 | AD40: ='2018-2019 B STATEMENT '!B155 -> 1000 | AE40: =AD40*0.89% -> 8.9 | AF40: 0 | AG40: 0 | AH40: =AG40*0.89% -> 0 | AI40: 0 | AJ40: 0 | AK40: =AJ40*0.89% -> 0 | AL40: 0 | AM40: 0 | AN40: =AM40*0.99% -> 0 | AO40: 0 | AP40: 0 | AQ40: =AP40*0.99% -> 0 | AR40: 0 | AS40: 0 | AT40: =AS40*0.99% -> 0 | AU40: 0 | AV40: 0 | AW40: =AV40*0.99% -> 0 | AX40: 0 | AY40: =O40+R40+U40+X40+AA40+AD40+AJ40+AG40+AM40+AP40+AS40+AV40 -> 2310
...

Sheet 2019-2020 New
A1: Member | B1: Date Join | C1: Membership Fee | D1: Expected Contribution | E1: Balance Brought Forward (*Incl. Catch up Fee) | F1: Catch-Up Fee | G1: Estimated 12 Months Contribution (Jul 2018-June 2019) | H1: Total Contribution for 12 Months | I1: Total outstanding contribution for 12 Months | J1: Closing Balance | K1: Total Bank Charges @ 1,1% | L1: Total Interest Earned @ 5,5% | M1: Penalty July 2019- June 2020 | N1: Capped Penalties Current Financial Year | O1: Share Value | P1: 43647 | Q1: Bank Charges @ 0,99% | R1: Amount Due | S1: Penalty | T1: 43678 | U1: Bank Charges @ 0,99% | V1: Amount Due | W1: Penalty | X1: 43709 | Y1: Bank Charges @ 0,99% | Z1: Amount Due | AA1: Penalty | AB1: 43739 | AC1: Bank Charges @ 0,99% | AD1: Amount Due | AE1: Penalty | AF1: 43770 | AG1: Bank Charges @ 0,99% | AH1: Amount Due | AI1: Penalty | AJ1: 43800 | AK1: Bank Charges @ 0,99% | AL1: Amount Due | AM1: Penalty | AN1: 43831 | AO1: Bank Charges @ 0,99% | AP1: Amount Due | AQ1: Penalty | AR1: 43862 | AS1: Bank Charges @ 0,99% | AT1: Amount Due | AU1: Penalty | AV1: 43891 | AW1: Bank Charges @ 0,99% | AX1: Amount Due | AY1: Penalty | AZ1: 43922 | BA1: Bank Charges @ 0,99% | BB1: Amount Due | BC1: Penalty | BD1: 43952 | BE1: Bank Charges @ 0,99% | BF1: Amount Due | BG1: Penalty | BH1: 43983 | BI1: Bank Charges @ 0,99% | BJ1: Amount Due | BK1: Penalty | BL1: Total Contribution for Current Year
A2: Member 1 | B2: 14/08/2018 | C2: 0 | D2: =200*12 -> 2400 | E2: =' 2018-2019'!J2 -> 800 | F2: =' 2018-2019'!F2 -> 200 | G2: =C2+D2 -> 2400 | H2: =BL2 -> 0 | I2: =G2-H2-C2 -> 2400 | J2: =I2+M2+E2 -> 4271.7906 | K2: =Q2+U2+Y2+AC2+AG2+AK2+AO2+AS2+AW2+BA2+BE2+BI2 -> 19.8 | L2: =(H2-K2-C2)*5.5% -> -1.089 | M2: =S2+W2+AA2+AE2+AI2+AM2+AQ2+AU2+AY2+BC2+BG2+BK2 -> 1071.7906 | N2: =M2 -> 1071.7906 | O2: =H2-K2-M2+L2 -> -1092.6796 | P2: 600 | Q2: =P2*0.99% -> 5.94 | R2: =E2+'Catch up Fee'!E2 -> 1000 | S2: =(R2-P2)*0.055 -> 22 | T2: 0 | U2: =T2*0.99% -> 0 | V2: =R2-T2+'Catch up Fee'!E2+S2 -> 1222 | W2: =(V2-T2)*0.055 -> 67.21 | X2: 0 | Y2: =X2*0.99% -> 0 | Z2: =V2-X2+'Catch up Fee'!E2+W2 -> 1489.21 | AA2: =(Z2-X2)*0.055 -> 81.90655 | AB2: 400 | AC2: =AB2*0.99% -> 3.96 | AD2: =Z2-AB2+'Catch up Fee'!E2+AA2 -> 1371.1165 | AE2: =(AD2-AB2)*0.055 -> 53.41141 | AF2: 200 | AG2: =AF2*0.99% -> 1.98 | AH2: =AD2-AF2+'Catch up Fee'!E2+AE2 -> 1424.528 | AI2: =(AH2-AF2)*0.055 -> 67.349038 | AJ2: 0 | AK2: =AJ2*0.99% -> 0 | AL2: =AH2-AJ2+'Catch up Fee'!E2+AI2 -> 1691.877 | AM2: =(AL2-AJ2)*0.055 -> 93.053235 | AN2: 0 | AO2: =AN2*0.99% -> 0 | AP2: =AL2-AN2+'Catch up Fee'!E2+AM2 -> 1984.9302 | AQ2: =(AP2-AN2)*0.055 -> 109.17116 | AR2: 0 | AS2: =AR2*0.99% -> 0 | AT2: =AP2-AR2+'Catch up Fee'!E2+AQ2 -> 2294.1014 | AU2: =(AT2-AR2)*0.055 -> 126.17558 | AV2: 800 | AW2: =AV2*0.99% -> 7.92 | AX2: =AT2-AV2+'Catch up Fee'!E2+AU2 -> 1820.277 | AY2: =(AX2-AV2)*0.055 -> 56.115233 | AZ2: 0 | BA2: =AZ2*0.99% -> 0 | BB2: =AX2-AZ2+'Catch up Fee'!E2+AY2 -> 2076.3922 | BC2: =(BB2-AZ2)*0.055 -> 114.20157 | BD2: 0 | BE2: =BD2*0.99% -> 0 | BF2: =BB2-BD2+'Catch up Fee'!E2+BC2 -> 2390.5938 | BG2: =(BF2-BD2)*0.055 -> 131.48266 | BH2: 0 | BI2: =BH2*0.99% -> 0 | BJ2: =BF2-BH2+'Catch up Fee'!E2+BG2 -> 2722.0764 | BK2: =(BJ2-BH2)*0.055 -> 149.7142
A3: Member 2 | B3: 16/02/2019 | C3: 0 | D3: =200*12 -> 2400 | E3: =' 2018-2019'!J3 -> 0 | F3: =' 2018-2019'!F3 -> 1600 | G3: =C3+D3 -> 2400 | H3: =BL3 -> 2000 | I3: =G3-H3-C3 -> 400 | J3: =I3+M3+E3 -> 1115.2596 | K3: =Q3+U3+Y3+AC3+AG3+AK3+AO3+AS3+AW3+BA3+BE3+BI3 -> 19.8 | L3: =(H3-K3-C3)*5.5% -> 108.911 | M3: =S3+W3+AA3+AE3+AI3+AM3+AQ3+AU3+AY3+BC3+BG3+BK3 -> 715.25963 | N3: =M3 -> 715.25963 | O3: =H3-K3-M3+L3 -> 1373.8514 | P3: 0 | Q3: =P3*0.99% -> 0 | R3: =E3+'Catch up Fee'!E3 -> 200 | S3: =(R3-P3)*0.055 -> 11 | T3: 0 | U3: =T3*0.99% -> 0 | V3: =R3-T3+'Catch up Fee'!E3+S3 -> 411 | W3: =(V3-T3)*0.055 -> 22.605 | X3: 0 | Y3: =X3*0.99% -> 0 | Z3: =V3-X3+'Catch up Fee'!E3+W3 -> 633.605 | AA3: =(Z3-X3)*0.055 -> 34.848275 | AB3: 0 | AC3: =AB3*0.99% -> 0 | AD3: =Z3-AB3+'Catch up Fee'!E3+AA3 -> 868.45328 | AE3: =(AD3-AB3)*0.055 -> 47.76493 | AF3: 0 | AG3: =AF3*0.99% -> 0 | AH3: =AD3-AF3+'Catch up Fee'!E3+AE3 -> 1116.2182 | AI3: =(AH3-AF3)*0.055 -> 61.392001 | AJ3: 0 | AK3: =AJ3*0.99% -> 0 | AL3: =AH3-AJ3+'Catch up Fee'!E3+AI3 -> 1377.6102 | AM3: =(AL3-AJ3)*0.055 -> 75.768561 | AN3: 0 | AO3: =AN3*0.99% -> 0 | AP3: =AL3-AN3+'Catch up Fee'!E3+AM3 -> 1653.3788 | AQ3: =(AP3-AN3)*0.055 -> 90.935832 | AR3: 0 | AS3: =AR3*0.99% -> 0 | AT3: =AP3-AR3+'Catch up Fee'!E3+AQ3 -> 1944.3146 | AU3: =(AT3-AR3)*0.055 -> 106.9373 | AV3: 0 | AW3: =AV3*0.99% -> 0 | AX3: =AT3-AV3+'Catch up Fee'!E3+AU3 -> 2251.2519 | AY3: =(AX3-AV3)*0.055 -> 123.81885 | BA3: =AZ3*0.99% -> 0 | BB3: =AX3-AZ3+'Catch up Fee'!E3+AY3 -> 2575.0708 | BC3: =(BB3-AZ3)*0.055 -> 141.62889 | BD3: 2000 | BE3: =BD3*0.99% -> 19.8 | BF3: =BB3-BD3+'Catch up Fee'!E3+BC3 -> 916.69965 | BG3: =(BF3-BD3)*0.055 -> -59.581519 | BH3: 0 | BI3: =BH3*0.99% -> 0 | BJ3: =BF3-BH3+'Catch up Fee'!E3+BG3 -> 1057.1181 | BK3: =(BJ3-BH3)*0.055 -> 58.141497 | BL3: =P3+T3+X3+AB3+AF3+AJ3+AR3+AN3+AV3+AZ3+BD3+BH3 -> 2000
